Workbook
Name CategoriasGasto: CONFIG!$A$5:$A$60
Name CategoriasIngreso: CONFIG!$C$5:$C$40
Name MediosPago: CONFIG!$E$5:$E$40
Name TodasCategorias: CONFIG!$M$5:$M$104

Sheet INSTRUCCIONES
A1: PLANILLA DE CONTROL DE GASTOS - Guia de uso
B4: Como empezar
B5: 1) Abri Google Drive > Nuevo > Subir archivo, subi este .xlsx y abrilo con Google Sheets.
B6: (o desde una planilla ya abierta: Archivo > Importar > Subir, y elegi 'Insertar hojas nuevas').
B7: 2) Anda a la solapa CONFIG y ajusta las categorias, los medios de pago y la cotizacion del dolar de cada mes.
B8: 3) Cargá todo en la solapa MOVIMIENTOS. Es la unica que se completa a mano todos los dias.
B9: 4) El resto de las solapas se calculan solas.
B11: Que hace cada solapa
B12: CONFIG - Las listas que alimentan los desplegables y la tabla de cotizacion del dolar por mes.
B13: Las categorias de gasto van en la columna A y las de ingreso en la columna C. La lista de la derecha
B14: se arma sola con las dos y es la que ves en el desplegable Categoria de MOVIMIENTOS.
B15: MOVIMIENTOS - El diario. Una fila por gasto o ingreso. Fecha, categoria, medio de pago e importe.
B16: GASTOS FIJOS - Los que se repiten todos los meses (alquiler, servicios, sueldos, monotributo).
... B36: para tener la curva del año. Para el reparto por categoria, selecciona la columna TOTAL y un grafico de torta.

Sheet CONFIG
A1: CONFIGURACION
A2: Edita libremente las listas. Lo que escribas aca es lo que aparece en los desplegables de MOVIMIENTOS.
A4: CATEGORIAS DE GASTO | C4: CATEGORIAS DE INGRESO | E4: MEDIOS DE PAGO | G4: Año | H4: Mes | I4: Clave | J4: Cotizacion U$D | M4: LISTA COMPLETA (automatica)
A5: Vivienda | C5: Ventas | E5: Efectivo | G5: 2026 | H5: 1 | I5: =IF($G5="","",$G5*100+$H5) | J5: 1540 | M5: =IF(ROW()-4<=COUNTA($A$5:$A$60),INDEX($A$5:$A$60,ROW()-4),IF(ROW()-4-COUNTA($A$5:$A$60)<=COUNTA($C$5:$C$40),INDEX($C$5:$C$40,ROW()-4-COUNTA($A$5:$A$60)),""))
A6: Servicios | C6: Cobranza de Cuotas | E6: Transferencia | G6: 2026 | H6: 2 | I6: =IF($G6="","",$G6*100+$H6) | J6: 1540 | M6: =IF(ROW()-4<=COUNTA($A$5:$A$60),INDEX($A$5:$A$60,ROW()-4),IF(ROW()-4-COUNTA($A$5:$A$60)<=COUNTA($C$5:$C$40),INDEX($C$5:$C$40,ROW()-4-COUNTA($A$5:$A$60)),""))
A7: Impuestos y Tasas | C7: Alquileres Cobrados | E7: Debito Automatico | G7: 2026 | H7: 3 | I7: =IF($G7="","",$G7*100+$H7) | J7: 1540 | M7: =IF(ROW()-4<=COUNTA($A$5:$A$60),INDEX($A$5:$A$60,ROW()-4),IF(ROW()-4-COUNTA($A$5:$A$60)<=COUNTA($C$5:$C$40),INDEX($C$5:$C$40,ROW()-4-COUNTA($A$5:$A$60)),""))
A8: Supermercado | C8: Intereses Ganados | E8: Tarjeta de Debito | G8: 2026 | H8: 4 | I8: =IF($G8="","",$G8*100+$H8) | J8: 1540 | M8: =IF(ROW()-4<=COUNTA($A$5:$A$60),INDEX($A$5:$A$60,ROW()-4),IF(ROW()-4-COUNTA($A$5:$A$60)<=COUNTA($C$5:$C$40),INDEX($C$5:$C$40,ROW()-4-COUNTA($A$5:$A$60)),""))
A9: Comida y Salidas | C9: Sueldo | E9: Tarjeta de Credito | G9: 2026 | H9: 5 | I9: =IF($G9="","",$G9*100+$H9) | J9: 1540 | M9: =IF(ROW()-4<=COUNTA($A$5:$A$60),INDEX($A$5:$A$60,ROW()-4),IF(ROW()-4-COUNTA($A$5:$A$60)<=COUNTA($C$5:$C$40),INDEX($C$5:$C$40,ROW()-4-COUNTA($A$5:$A$60)),""))
A10: Transporte | C10: Honorarios | E10: Mercado Pago | G10: 2026 | H10: 6 | I10: =IF($G10="","",$G10*100+$H10) | J10: 1540 | M10: =IF(ROW()-4<=COUNTA($A$5:$A$60),INDEX($A$5:$A$60,ROW()-4),IF(ROW()-4-COUNTA($A$5:$A$60)<=COUNTA($C$5:$C$40),INDEX($C$5:$C$40,ROW()-4-COUNTA($A$5:$A$60)),""))
A11: Combustible | C11: Devoluciones | E11: Cheque | G11: 2026 | H11: 7 | I11: =IF($G11="","",$G11*100+$H11) | J11: 1540 | M11: =IF(ROW()-4<=COUNTA($A$5:$A$60),INDEX($A$5:$A$60,ROW()-4),IF(ROW()-4-COUNTA($A$5:$A$60)<=COUNTA($C$5:$C$40),INDEX($C$5:$C$40,ROW()-4-COUNTA($A$5:$A$60)),""))
A12: Vehiculos - Mantenimiento | C12: Aportes de Socios | E12: Dolares Efectivo | G12: 2026 | H12: 8 | I12: =IF($G12="","",$G12*100+$H12) | J12: 1540 | M12: =IF(ROW()-4<=COUNTA($A$5:$A$60),INDEX($A$5:$A$60,ROW()-4),IF(ROW()-4-COUNTA($A$5:$A$60)<=COUNTA($C$5:$C$40),INDEX($C$5:$C$40,ROW()-4-COUNTA($A$5:$A$60)),""))
A13: Seguros | C13: Otros Ingresos | G13: 2026 | H13: 9 | I13: =IF($G13="","",$G13*100+$H13) | J13: 1540 | M13: =IF(ROW()-4<=COUNTA($A$5:$A$60),INDEX($A$5:$A$60,ROW()-4),IF(ROW()-4-COUNTA($A$5:$A$60)<=COUNTA($C$5:$C$40),INDEX($C$5:$C$40,ROW()-4-COUNTA($A$5:$A$60)),""))
A14: Salud | G14: 2026 | H14: 10 | I14: =IF($G14="","",$G14*100+$H14) | J14: 1540 | M14: =IF(ROW()-4<=COUNTA($A$5:$A$60),INDEX($A$5:$A$60,ROW()-4),IF(ROW()-4-COUNTA($A$5:$A$60)<=COUNTA($C$5:$C$40),INDEX($C$5:$C$40,ROW()-4-COUNTA($A$5:$A$60)),""))
A15: Educacion | G15: 2026 | H15: 11 | I15: =IF($G15="","",$G15*100+$H15) | J15: 1540 | M15: =IF(ROW()-4<=COUNTA($A$5:$A$60),INDEX($A$5:$A$60,ROW()-4),IF(ROW()-4-COUNTA($A$5:$A$60)<=COUNTA($C$5:$C$40),INDEX($C$5:$C$40,ROW()-4-COUNTA($A$5:$A$60)),""))
A16: Indumentaria | G16: 2026 | H16: 12 | I16: =IF($G16="","",$G16*100+$H16) | J16: 1540 | M16: =IF(ROW()-4<=COUNTA($A$5:$A$60),INDEX($A$5:$A$60,ROW()-4),IF(ROW()-4-COUNTA($A$5:$A$60)<=COUNTA($C$5:$C$40),INDEX($C$5:$C$40,ROW()-4-COUNTA($A$5:$A$60)),""))
A17: Sueldos y Cargas | G17: 2027 | H17: 1 | I17: =IF($G17="","",$G17*100+$H17) | J17: 1540 | M17: =IF(ROW()-4<=COUNTA($A$5:$A$60),INDEX($A$5:$A$60,ROW()-4),IF(ROW()-4-COUNTA($A$5:$A$60)<=COUNTA($C$5:$C$40),INDEX($C$5:$C$40,ROW()-4-COUNTA($A$5:$A$60)),""))
A18: Honorarios Profesionales | G18: 2027 | H18: 2 | I18: =IF($G18="","",$G18*100+$H18) | J18: 1540 | M18: =IF(ROW()-4<=COUNTA($A$5:$A$60),INDEX($A$5:$A$60,ROW()-4),IF(ROW()-4-COUNTA($A$5:$A$60)<=COUNTA($C$5:$C$40),INDEX($C$5:$C$40,ROW()-4-COUNTA($A$5:$A$60)),""))
A19: Monotributo / AFIP | G19: 2027 | H19: 3 | I19: =IF($G19="","",$G19*100+$H19) | J19: 1540 | M19: =IF(ROW()-4<=COUNTA($A$5:$A$60),INDEX($A$5:$A$60,ROW()-4),IF(ROW()-4-COUNTA($A$5:$A$60)<=COUNTA($C$5:$C$40),INDEX($C$5:$C$40,ROW()-4-COUNTA($A$5:$A$60)),""))
A20: Bancos y Comisiones | G20: 2027 | H20: 4 | I20: =IF($G20="","",$G20*100+$H20) | J20: 1540 | M20: =IF(ROW()-4<=COUNTA($A$5:$A$60),INDEX($A$5:$A$60,ROW()-4),IF(ROW()-4-COUNTA($A$5:$A$60)<=COUNTA($C$5:$C$40),INDEX($C$5:$C$40,ROW()-4-COUNTA($A$5:$A$60)),""))
A21: Tarjetas - Cuotas | G21: 2027 | H21: 5 | I21: =IF($G21="","",$G21*100+$H21) | J21: 1540 | M21: =IF(ROW()-4<=COUNTA($A$5:$A$60),INDEX($A$5:$A$60,ROW()-4),IF(ROW()-4-COUNTA($A$5:$A$60)<=COUNTA($C$5:$C$40),INDEX($C$5:$C$40,ROW()-4-COUNTA($A$5:$A$60)),""))
A22: Prestamos e Intereses | G22: 2027 | H22: 6 | I22: =IF($G22="","",$G22*100+$H22) | J22: 1540 | M22: =IF(ROW()-4<=COUNTA($A$5:$A$60),INDEX($A$5:$A$60,ROW()-4),IF(ROW()-4-COUNTA($A$5:$A$60)<=COUNTA($C$5:$C$40),INDEX($C$5:$C$40,ROW()-4-COUNTA($A$5:$A$60)),""))
A23: Inversiones | G23: 2027 | H23: 7 | I23: =IF($G23="","",$G23*100+$H23) | J23: 1540 | M23: =IF(ROW()-4<=COUNTA($A$5:$A$60),INDEX($A$5:$A$60,ROW()-4),IF(ROW()-4-COUNTA($A$5:$A$60)<=COUNTA($C$5:$C$40),INDEX($C$5:$C$40,ROW()-4-COUNTA($A$5:$A$60)),""))
A24: Mercaderia / Stock | G24: 2027 | H24: 8 | I24: =IF($G24="","",$G24*100+$H24) | J24: 1540 | M24: =IF(ROW()-4<=COUNTA($A$5:$A$60),INDEX($A$5:$A$60,ROW()-4),IF(ROW()-4-COUNTA($A$5:$A$60)<=COUNTA($C$5:$C$40),INDEX($C$5:$C$40,ROW()-4-COUNTA($A$5:$A$60)),""))
A25: Fletes y Logistica | G25: 2027 | H25: 9 | I25: =IF($G25="","",$G25*100+$H25) | J25: 1540 | M25: =IF(ROW()-4<=COUNTA($A$5:$A$60),INDEX($A$5:$A$60,ROW()-4),IF(ROW()-4-COUNTA($A$5:$A$60)<=COUNTA($C$5:$C$40),INDEX($C$5:$C$40,ROW()-4-COUNTA($A$5:$A$60)),""))
... A28: Alquileres Comerciales | G28: 2027 | H28: 12 | I28: =IF($G28="","",$G28*100+$H28) | J28: 1540 | M28: =IF(ROW()-4<=COUNTA($A$5:$A$60),INDEX($A$5:$A$60,ROW()-4),IF(ROW()-4-COUNTA($A$5:$A$60)<=COUNTA($C$5:$C$40),INDEX($C$5:$C$40,ROW()-4-COUNTA($A$5:$A$60)),""))
A29: Viajes | M29: =IF(ROW()-4<=COUNTA($A$5:$A$60),INDEX($A$5:$A$60,ROW()-4),IF(ROW()-4-COUNTA($A$5:$A$60)<=COUNTA($C$5:$C$40),INDEX($C$5:$C$40,ROW()-4-COUNTA($A$5:$A$60)),""))
A30: Regalos y Donaciones | G30: La columna Clave la usa la planilla para buscar la cotizacion. No la toques. | M30: =IF(ROW()-4<=COUNTA($A$5:$A$60),INDEX($A$5:$A$60,ROW()-4),IF(ROW()-4-COUNTA($A$5:$A$60)<=COUNTA($C$5:$C$40),INDEX($C$5:$C$40,ROW()-4-COUNTA($A$5:$A$60)),""))
A31: Mascotas | M31: =IF(ROW()-4<=COUNTA($A$5:$A$60),INDEX($A$5:$A$60,ROW()-4),IF(ROW()-4-COUNTA($A$5:$A$60)<=COUNTA($C$5:$C$40),INDEX($C$5:$C$40,ROW()-4-COUNTA($A$5:$A$60)),""))
A32: Ocio y Suscripciones | M32: =IF(ROW()-4<=COUNTA($A$5:$A$60),INDEX($A$5:$A$60,ROW()-4),IF(ROW()-4-COUNTA($A$5:$A$60)<=COUNTA($C$5:$C$40),INDEX($C$5:$C$40,ROW()-4-COUNTA($A$5:$A$60)),""))
A33: Gastos Varios | M33: =IF(ROW()-4<=COUNTA($A$5:$A$60),INDEX($A$5:$A$60,ROW()-4),IF(ROW()-4-COUNTA($A$5:$A$60)<=COUNTA($C$5:$C$40),INDEX($C$5:$C$40,ROW()-4-COUNTA($A$5:$A$60)),""))
M34: =IF(ROW()-4<=COUNTA($A$5:$A$60),INDEX($A$5:$A$60,ROW()-4),IF(ROW()-4-COUNTA($A$5:$A$60)<=COUNTA($C$5:$C$40),INDEX($C$5:$C$40,ROW()-4-COUNTA($A$5:$A$60)),""))
M35: =IF(ROW()-4<=COUNTA($A$5:$A$60),INDEX($A$5:$A$60,ROW()-4),IF(ROW()-4-COUNTA($A$5:$A$60)<=COUNTA($C$5:$C$40),INDEX($C$5:$C$40,ROW()-4-COUNTA($A$5:$A$60)),""))
M36: =IF(ROW()-4<=COUNTA($A$5:$A$60),INDEX($A$5:$A$60,ROW()-4),IF(ROW()-4-COUNTA($A$5:$A$60)<=COUNTA($C$5:$C$40),INDEX($C$5:$C$40,ROW()-4-COUNTA($A$5:$A$60)),""))
M37: =IF(ROW()-4<=COUNTA($A$5:$A$60),INDEX($A$5:$A$60,ROW()-4),IF(ROW()-4-COUNTA($A$5:$A$60)<=COUNTA($C$5:$C$40),INDEX($C$5:$C$40,ROW()-4-COUNTA($A$5:$A$60)),""))
M38: =IF(ROW()-4<=COUNTA($A$5:$A$60),INDEX($A$5:$A$60,ROW()-4),IF(ROW()-4-COUNTA($A$5:$A$60)<=COUNTA($C$5:$C$40),INDEX($C$5:$C$40,ROW()-4-COUNTA($A$5:$A$60)),""))
M39: =IF(ROW()-4<=COUNTA($A$5:$A$60),INDEX($A$5:$A$60,ROW()-4),IF(ROW()-4-COUNTA($A$5:$A$60)<=COUNTA($C$5:$C$40),INDEX($C$5:$C$40,ROW()-4-COUNTA($A$5:$A$60)),""))
M40: =IF(ROW()-4<=COUNTA($A$5:$A$60),INDEX($A$5:$A$60,ROW()-4),IF(ROW()-4-COUNTA($A$5:$A$60)<=COUNTA($C$5:$C$40),INDEX($C$5:$C$40,ROW()-4-COUNTA($A$5:$A$60)),""))
M41: =IF(ROW()-4<=COUNTA($A$5:$A$60),INDEX($A$5:$A$60,ROW()-4),IF(ROW()-4-COUNTA($A$5:$A$60)<=COUNTA($C$5:$C$40),INDEX($C$5:$C$40,ROW()-4-COUNTA($A$5:$A$60)),""))
M42: =IF(ROW()-4<=COUNTA($A$5:$A$60),INDEX($A$5:$A$60,ROW()-4),IF(ROW()-4-COUNTA($A$5:$A$60)<=COUNTA($C$5:$C$40),INDEX($C$5:$C$40,ROW()-4-COUNTA($A$5:$A$60)),""))
M43: =IF(ROW()-4<=COUNTA($A$5:$A$60),INDEX($A$5:$A$60,ROW()-4),IF(ROW()-4-COUNTA($A$5:$A$60)<=COUNTA($C$5:$C$40),INDEX($C$5:$C$40,ROW()-4-COUNTA($A$5:$A$60)),""))
...

Sheet MOVIMIENTOS
A1: MOVIMIENTOS - Gastos e Ingresos
A2: Una fila por movimiento. Solo se completan las columnas blancas; Año, Mes e Importe U$D se calculan solos.
A4: Fecha | B4: Año | C4: Mes | D4: Tipo | E4: Categoria | F4: Detalle | G4: Medio de Pago | H4: Moneda | I4: Importe | J4: Importe U$D | K4: Fijo / Variable | L4: Estado | M4: Notas
A5: =DATE(2026,1,5) | B5: =IF($A5="","",YEAR($A5)) | C5: =IF($A5="","",MONTH($A5)) | D5: Gasto | E5: Vivienda | F5: Alquiler oficina enero | G5: Transferencia | H5: $ | I5: 850000 | J5: =IF($I5="","",IF($H5="U$D",$I5,IFERROR($I5/VLOOKUP($B5*100+$C5,CONFIG!$I$5:$J$60,2,FALSE),"sin cotiz"))) | K5: Fijo | L5: Pagado | M5: EJEMPLO - borra estas 5 filas
A6: =DATE(2026,1,7) | B6: =IF($A6="","",YEAR($A6)) | C6: =IF($A6="","",MONTH($A6)) | D6: Gasto | E6: Combustible | F6: Nafta Peugeot 3008 | G6: Tarjeta de Credito | H6: $ | I6: 62000 | J6: =IF($I6="","",IF($H6="U$D",$I6,IFERROR($I6/VLOOKUP($B6*100+$C6,CONFIG!$I$5:$J$60,2,FALSE),"sin cotiz"))) | K6: Variable | L6: Pagado | M6: EJEMPLO
A7: =DATE(2026,1,10) | B7: =IF($A7="","",YEAR($A7)) | C7: =IF($A7="","",MONTH($A7)) | D7: Ingreso | E7: Cobranza de Cuotas | F7: Cuota Juan Financiera | G7: Transferencia | H7: U$D | I7: 1000 | J7: =IF($I7="","",IF($H7="U$D",$I7,IFERROR($I7/VLOOKUP($B7*100+$C7,CONFIG!$I$5:$J$60,2,FALSE),"sin cotiz"))) | K7: Fijo | L7: Pagado | M7: EJEMPLO
A8: =DATE(2026,1,12) | B8: =IF($A8="","",YEAR($A8)) | C8: =IF($A8="","",MONTH($A8)) | D8: Gasto | E8: Monotributo / AFIP | F8: Monotributo enero | G8: Debito Automatico | H8: $ | I8: 48000 | J8: =IF($I8="","",IF($H8="U$D",$I8,IFERROR($I8/VLOOKUP($B8*100+$C8,CONFIG!$I$5:$J$60,2,FALSE),"sin cotiz"))) | K8: Fijo | L8: Pagado | M8: EJEMPLO
A9: =DATE(2026,1,15) | B9: =IF($A9="","",YEAR($A9)) | C9: =IF($A9="","",MONTH($A9)) | D9: Gasto | E9: Sueldos y Cargas | F9: Sueldo Lucas | G9: Transferencia | H9: $ | I9: 900000 | J9: =IF($I9="","",IF($H9="U$D",$I9,IFERROR($I9/VLOOKUP($B9*100+$C9,CONFIG!$I$5:$J$60,2,FALSE),"sin cotiz"))) | K9: Fijo | L9: Pendiente | M9: EJEMPLO - queda como pendiente a proposito
B10: =IF($A10="","",YEAR($A10)) | C10: =IF($A10="","",MONTH($A10)) | J10: =IF($I10="","",IF($H10="U$D",$I10,IFERROR($I10/VLOOKUP($B10*100+$C10,CONFIG!$I$5:$J$60,2,FALSE),"sin cotiz")))
B11: =IF($A11="","",YEAR($A11)) | C11: =IF($A11="","",MONTH($A11)) | J11: =IF($I11="","",IF($H11="U$D",$I11,IFERROR($I11/VLOOKUP($B11*100+$C11,CONFIG!$I$5:$J$60,2,FALSE),"sin cotiz")))
B12: =IF($A12="","",YEAR($A12)) | C12: =IF($A12="","",MONTH($A12)) | J12: =IF($I12="","",IF($H12="U$D",$I12,IFERROR($I12/VLOOKUP($B12*100+$C12,CONFIG!$I$5:$J$60,2,FALSE),"sin cotiz")))
B13: =IF($A13="","",YEAR($A13)) | C13: =IF($A13="","",MONTH($A13)) | J13: =IF($I13="","",IF($H13="U$D",$I13,IFERROR($I13/VLOOKUP($B13*100+$C13,CONFIG!$I$5:$J$60,2,FALSE),"sin cotiz")))
B14: =IF($A14="","",YEAR($A14)) | C14: =IF($A14="","",MONTH($A14)) | J14: =IF($I14="","",IF($H14="U$D",$I14,IFERROR($I14/VLOOKUP($B14*100+$C14,CONFIG!$I$5:$J$60,2,FALSE),"sin cotiz")))
B15: =IF($A15="","",YEAR($A15)) | C15: =IF($A15="","",MONTH($A15)) | J15: =IF($I15="","",IF($H15="U$D",$I15,IFERROR($I15/VLOOKUP($B15*100+$C15,CONFIG!$I$5:$J$60,2,FALSE),"sin cotiz")))
B16: =IF($A16="","",YEAR($A16)) | C16: =IF($A16="","",MONTH($A16)) | J16: =IF($I16="","",IF($H16="U$D",$I16,IFERROR($I16/VLOOKUP($B16*100+$C16,CONFIG!$I$5:$J$60,2,FALSE),"sin cotiz")))
B17: =IF($A17="","",YEAR($A17)) | C17: =IF($A17="","",MONTH($A17)) | J17: =IF($I17="","",IF($H17="U$D",$I17,IFERROR($I17/VLOOKUP($B17*100+$C17,CONFIG!$I$5:$J$60,2,FALSE),"sin cotiz")))
B18: =IF($A18="","",YEAR($A18)) | C18: =IF($A18="","",MONTH($A18)) | J18: =IF($I18="","",IF($H18="U$D",$I18,IFERROR($I18/VLOOKUP($B18*100+$C18,CONFIG!$I$5:$J$60,2,FALSE),"sin cotiz")))
B19: =IF($A19="","",YEAR($A19)) | C19: =IF($A19="","",MONTH($A19)) | J19: =IF($I19="","",IF($H19="U$D",$I19,IFERROR($I19/VLOOKUP($B19*100+$C19,CONFIG!$I$5:$J$60,2,FALSE),"sin cotiz")))
B20: =IF($A20="","",YEAR($A20)) | C20: =IF($A20="","",MONTH($A20)) | J20: =IF($I20="","",IF($H20="U$D",$I20,IFERROR($I20/VLOOKUP($B20*100+$C20,CONFIG!$I$5:$J$60,2,FALSE),"sin cotiz")))
B21: =IF($A21="","",YEAR($A21)) | C21: =IF($A21="","",MONTH($A21)) | J21: =IF($I21="","",IF($H21="U$D",$I21,IFERROR($I21/VLOOKUP($B21*100+$C21,CONFIG!$I$5:$J$60,2,FALSE),"sin cotiz")))
... B804: =IF($A804="","",YEAR($A804)) | C804: =IF($A804="","",MONTH($A804)) | J804: =IF($I804="","",IF($H804="U$D",$I804,IFERROR($I804/VLOOKUP($B804*100+$C804,CONFIG!$I$5:$J$60,2,FALSE),"sin cotiz")))

Sheet GASTOS FIJOS
A1: GASTOS FIJOS MENSUALES
A2: Los que se repiten todos los meses. Sirve de checklist: mira que ninguno se te escape al cargar MOVIMIENTOS.
A4: Concepto | B4: Categoria | C4: Importe | D4: Moneda | E4: Dia de Vencimiento | F4: Medio de Pago | G4: Activo | H4: Importe U$D estimado | I4: Notas
A5: Alquiler oficina | B5: Vivienda | C5: 850000 | D5: $ | E5: 10 | F5: Transferencia | G5: Si | H5: =IF($C5="","",IF($D5="U$D",$C5,IFERROR($C5/VLOOKUP(MAX(CONFIG!$I$5:$I$60),CONFIG!$I$5:$J$60,2,FALSE),"")))
A6: Monotributo | B6: Monotributo / AFIP | C6: 48000 | D6: $ | E6: 20 | F6: Debito Automatico | G6: Si | H6: =IF($C6="","",IF($D6="U$D",$C6,IFERROR($C6/VLOOKUP(MAX(CONFIG!$I$5:$I$60),CONFIG!$I$5:$J$60,2,FALSE),"")))
A7: Contadora | B7: Honorarios Profesionales | C7: 120000 | D7: $ | E7: 10 | F7: Transferencia | G7: Si | H7: =IF($C7="","",IF($D7="U$D",$C7,IFERROR($C7/VLOOKUP(MAX(CONFIG!$I$5:$I$60),CONFIG!$I$5:$J$60,2,FALSE),"")))
A8: Internet + celulares | B8: Servicios | C8: 75000 | D8: $ | E8: 15 | F8: Debito Automatico | G8: Si | H8: =IF($C8="","",IF($D8="U$D",$C8,IFERROR($C8/VLOOKUP(MAX(CONFIG!$I$5:$I$60),CONFIG!$I$5:$J$60,2,FALSE),"")))
H9: =IF($C9="","",IF($D9="U$D",$C9,IFERROR($C9/VLOOKUP(MAX(CONFIG!$I$5:$I$60),CONFIG!$I$5:$J$60,2,FALSE),"")))
H10: =IF($C10="","",IF($D10="U$D",$C10,IFERROR($C10/VLOOKUP(MAX(CONFIG!$I$5:$I$60),CONFIG!$I$5:$J$60,2,FALSE),"")))
H11: =IF($C11="","",IF($D11="U$D",$C11,IFERROR($C11/VLOOKUP(MAX(CONFIG!$I$5:$I$60),CONFIG!$I$5:$J$60,2,FALSE),"")))
H12: =IF($C12="","",IF($D12="U$D",$C12,IFERROR($C12/VLOOKUP(MAX(CONFIG!$I$5:$I$60),CONFIG!$I$5:$J$60,2,FALSE),"")))
H13: =IF($C13="","",IF($D13="U$D",$C13,IFERROR($C13/VLOOKUP(MAX(CONFIG!$I$5:$I$60),CONFIG!$I$5:$J$60,2,FALSE),"")))
H14: =IF($C14="","",IF($D14="U$D",$C14,IFERROR($C14/VLOOKUP(MAX(CONFIG!$I$5:$I$60),CONFIG!$I$5:$J$60,2,FALSE),"")))
H15: =IF($C15="","",IF($D15="U$D",$C15,IFERROR($C15/VLOOKUP(MAX(CONFIG!$I$5:$I$60),CONFIG!$I$5:$J$60,2,FALSE),"")))
H16: =IF($C16="","",IF($D16="U$D",$C16,IFERROR($C16/VLOOKUP(MAX(CONFIG!$I$5:$I$60),CONFIG!$I$5:$J$60,2,FALSE),"")))
H17: =IF($C17="","",IF($D17="U$D",$C17,IFERROR($C17/VLOOKUP(MAX(CONFIG!$I$5:$I$60),CONFIG!$I$5:$J$60,2,FALSE),"")))
H18: =IF($C18="","",IF($D18="U$D",$C18,IFERROR($C18/VLOOKUP(MAX(CONFIG!$I$5:$I$60),CONFIG!$I$5:$J$60,2,FALSE),"")))
H19: =IF($C19="","",IF($D19="U$D",$C19,IFERROR($C19/VLOOKUP(MAX(CONFIG!$I$5:$I$60),CONFIG!$I$5:$J$60,2,FALSE),"")))
H20: =IF($C20="","",IF($D20="U$D",$C20,IFERROR($C20/VLOOKUP(MAX(CONFIG!$I$5:$I$60),CONFIG!$I$5:$J$60,2,FALSE),"")))
... H64: =IF($C64="","",IF($D64="U$D",$C64,IFERROR($C64/VLOOKUP(MAX(CONFIG!$I$5:$I$60),CONFIG!$I$5:$J$60,2,FALSE),"")))
A66: TOTAL FIJOS ACTIVOS ($) | C66: =SUMIFS($C$5:$C$64,$G$5:$G$64,"Si",$D$5:$D$64,"$")
A67: TOTAL FIJOS ACTIVOS (U$D) | C67: =SUMIFS($C$5:$C$64,$G$5:$G$64,"Si",$D$5:$D$64,"U$D")

Sheet TARJETAS Y CUOTAS
A1: TARJETAS Y COMPRAS EN CUOTAS
A2: Cargá la compra una sola vez y la planilla te dice cuanto pagaste, cuanto falta y en que mes termina.
A4: Concepto | B4: Tarjeta / Acreedor | C4: Fecha de Compra | D4: Cant. Cuotas | E4: Valor Cuota | F4: Moneda | G4: Total | H4: Cuotas Pagadas | I4: Pagado | J4: Saldo | K4: Ultima Cuota | L4: Estado
A5: Peugeot Partner | B5: Banco Galicia | C5: =DATE(2025,11,10) | D5: 12 | E5: 350000 | F5: $ | G5: =IF($D5="","",$D5*$E5) | H5: 3 | I5: =IF($H5="","",$H5*$E5) | J5: =IF($D5="","",($D5-N($H5))*$E5) | K5: =IF($C5="","",EDATE($C5,$D5-1)) | L5: =IF($D5="","",IF(N($H5)>=$D5,"Cancelado","Vigente"))
A6: Notebook | B6: Visa Santander | C6: =DATE(2026,1,20) | D6: 6 | E6: 180000 | F6: $ | G6: =IF($D6="","",$D6*$E6) | H6: 0 | I6: =IF($H6="","",$H6*$E6) | J6: =IF($D6="","",($D6-N($H6))*$E6) | K6: =IF($C6="","",EDATE($C6,$D6-1)) | L6: =IF($D6="","",IF(N($H6)>=$D6,"Cancelado","Vigente"))
G7: =IF($D7="","",$D7*$E7) | I7: =IF($H7="","",$H7*$E7) | J7: =IF($D7="","",($D7-N($H7))*$E7) | K7: =IF($C7="","",EDATE($C7,$D7-1)) | L7: =IF($D7="","",IF(N($H7)>=$D7,"Cancelado","Vigente"))
G8: =IF($D8="","",$D8*$E8) | I8: =IF($H8="","",$H8*$E8) | J8: =IF($D8="","",($D8-N($H8))*$E8) | K8: =IF($C8="","",EDATE($C8,$D8-1)) | L8: =IF($D8="","",IF(N($H8)>=$D8,"Cancelado","Vigente"))
G9: =IF($D9="","",$D9*$E9) | I9: =IF($H9="","",$H9*$E9) | J9: =IF($D9="","",($D9-N($H9))*$E9) | K9: =IF($C9="","",EDATE($C9,$D9-1)) | L9: =IF($D9="","",IF(N($H9)>=$D9,"Cancelado","Vigente"))
G10: =IF($D10="","",$D10*$E10) | I10: =IF($H10="","",$H10*$E10) | J10: =IF($D10="","",($D10-N($H10))*$E10) | K10: =IF($C10="","",EDATE($C10,$D10-1)) | L10: =IF($D10="","",IF(N($H10)>=$D10,"Cancelado","Vigente"))
G11: =IF($D11="","",$D11*$E11) | I11: =IF($H11="","",$H11*$E11) | J11: =IF($D11="","",($D11-N($H11))*$E11) | K11: =IF($C11="","",EDATE($C11,$D11-1)) | L11: =IF($D11="","",IF(N($H11)>=$D11,"Cancelado","Vigente"))
G12: =IF($D12="","",$D12*$E12) | I12: =IF($H12="","",$H12*$E12) | J12: =IF($D12="","",($D12-N($H12))*$E12) | K12: =IF($C12="","",EDATE($C12,$D12-1)) | L12: =IF($D12="","",IF(N($H12)>=$D12,"Cancelado","Vigente"))
G13: =IF($D13="","",$D13*$E13) | I13: =IF($H13="","",$H13*$E13) | J13: =IF($D13="","",($D13-N($H13))*$E13) | K13: =IF($C13="","",EDATE($C13,$D13-1)) | L13: =IF($D13="","",IF(N($H13)>=$D13,"Cancelado","Vigente"))
G14: =IF($D14="","",$D14*$E14) | I14: =IF($H14="","",$H14*$E14) | J14: =IF($D14="","",($D14-N($H14))*$E14) | K14: =IF($C14="","",EDATE($C14,$D14-1)) | L14: =IF($D14="","",IF(N($H14)>=$D14,"Cancelado","Vigente"))
G15: =IF($D15="","",$D15*$E15) | I15: =IF($H15="","",$H15*$E15) | J15: =IF($D15="","",($D15-N($H15))*$E15) | K15: =IF($C15="","",EDATE($C15,$D15-1)) | L15: =IF($D15="","",IF(N($H15)>=$D15,"Cancelado","Vigente"))
G16: =IF($D16="","",$D16*$E16) | I16: =IF($H16="","",$H16*$E16) | J16: =IF($D16="","",($D16-N($H16))*$E16) | K16: =IF($C16="","",EDATE($C16,$D16-1)) | L16: =IF($D16="","",IF(N($H16)>=$D16,"Cancelado","Vigente"))
G17: =IF($D17="","",$D17*$E17) | I17: =IF($H17="","",$H17*$E17) | J17: =IF($D17="","",($D17-N($H17))*$E17) | K17: =IF($C17="","",EDATE($C17,$D17-1)) | L17: =IF($D17="","",IF(N($H17)>=$D17,"Cancelado","Vigente"))
G18: =IF($D18="","",$D18*$E18) | I18: =IF($H18="","",$H18*$E18) | J18: =IF($D18="","",($D18-N($H18))*$E18) | K18: =IF($C18="","",EDATE($C18,$D18-1)) | L18: =IF($D18="","",IF(N($H18)>=$D18,"Cancelado","Vigente"))
... G84: =IF($D84="","",$D84*$E84) | I84: =IF($H84="","",$H84*$E84) | J84: =IF($D84="","",($D84-N($H84))*$E84) | K84: =IF($C84="","",EDATE($C84,$D84-1)) | L84: =IF($D84="","",IF(N($H84)>=$D84,"Cancelado","Vigente"))
A87: SALDO TOTAL EN CUOTAS ($) | J87: =SUMIFS($J$5:$J$84,$F$5:$F$84,"$")
A88: SALDO TOTAL EN CUOTAS (U$D) | J88: =SUMIFS($J$5:$J$84,$F$5:$F$84,"U$D")

Sheet RESUMEN MENSUAL
A1: RESUMEN MENSUAL POR CATEGORIA
A2: Todo sale solo de MOVIMIENTOS. Cambia el año de la celda amarilla y se recalcula entero.
A3: AÑO: | B3: 2026 | C3: <- cambia el año aca
A5: mes nro | B5: 1 | C5: 2 | D5: 3 | E5: 4 | F5: 5 | G5: 6 | H5: 7 | I5: 8 | J5: 9 | K5: 10 | L5: 11 | M5: 12
A6: CATEGORIA | B6: Enero | C6: Febrero | D6: Marzo | E6: Abril | F6: Mayo | G6: Junio | H6: Julio | I6: Agosto | J6: Septiembre | K6: Octubre | L6: Noviembre | M6: Diciembre | N6: TOTAL AÑO
A7: Vivienda | B7: =SUMIFS(MOVIMIENTOS!$J:$J,MOVIMIENTOS!$E:$E,$A7,MOVIMIENTOS!$B:$B,$B$3,MOVIMIENTOS!$C:$C,B$5,MOVIMIENTOS!$D:$D,"Gasto") | C7: =SUMIFS(MOVIMIENTOS!$J:$J,MOVIMIENTOS!$E:$E,$A7,MOVIMIENTOS!$B:$B,$B$3,MOVIMIENTOS!$C:$C,C$5,MOVIMIENTOS!$D:$D,"Gasto") | D7: =SUMIFS(MOVIMIENTOS!$J:$J,MOVIMIENTOS!$E:$E,$A7,MOVIMIENTOS!$B:$B,$B$3,MOVIMIENTOS!$C:$C,D$5,MOVIMIENTOS!$D:$D,"Gasto") | E7: =SUMIFS(MOVIMIENTOS!$J:$J,MOVIMIENTOS!$E:$E,$A7,MOVIMIENTOS!$B:$B,$B$3,MOVIMIENTOS!$C:$C,E$5,MOVIMIENTOS!$D:$D,"Gasto") | F7: =SUMIFS(MOVIMIENTOS!$J:$J,MOVIMIENTOS!$E:$E,$A7,MOVIMIENTOS!$B:$B,$B$3,MOVIMIENTOS!$C:$C,F$5,MOVIMIENTOS!$D:$D,"Gasto") | G7: =SUMIFS(MOVIMIENTOS!$J:$J,MOVIMIENTOS!$E:$E,$A7,MOVIMIENTOS!$B:$B,$B$3,MOVIMIENTOS!$C:$C,G$5,MOVIMIENTOS!$D:$D,"Gasto") | H7: =SUMIFS(MOVIMIENTOS!$J:$J,MOVIMIENTOS!$E:$E,$A7,MOVIMIENTOS!$B:$B,$B$3,MOVIMIENTOS!$C:$C,H$5,MOVIMIENTOS!$D:$D,"Gasto") | I7: =SUMIFS(MOVIMIENTOS!$J:$J,MOVIMIENTOS!$E:$E,$A7,MOVIMIENTOS!$B:$B,$B$3,MOVIMIENTOS!$C:$C,I$5,MOVIMIENTOS!$D:$D,"Gasto") | ... M7: =SUMIFS(MOVIMIENTOS!$J:$J,MOVIMIENTOS!$E:$E,$A7,MOVIMIENTOS!$B:$B,$B$3,MOVIMIENTOS!$C:$C,M$5,MOVIMIENTOS!$D:$D,"Gasto") | N7: =SUM($B7:$M7)
A8: Servicios | B8: =SUMIFS(MOVIMIENTOS!$J:$J,MOVIMIENTOS!$E:$E,$A8,MOVIMIENTOS!$B:$B,$B$3,MOVIMIENTOS!$C:$C,B$5,MOVIMIENTOS!$D:$D,"Gasto") | C8: =SUMIFS(MOVIMIENTOS!$J:$J,MOVIMIENTOS!$E:$E,$A8,MOVIMIENTOS!$B:$B,$B$3,MOVIMIENTOS!$C:$C,C$5,MOVIMIENTOS!$D:$D,"Gasto") | D8: =SUMIFS(MOVIMIENTOS!$J:$J,MOVIMIENTOS!$E:$E,$A8,MOVIMIENTOS!$B:$B,$B$3,MOVIMIENTOS!$C:$C,D$5,MOVIMIENTOS!$D:$D,"Gasto") | E8: =SUMIFS(MOVIMIENTOS!$J:$J,MOVIMIENTOS!$E:$E,$A8,MOVIMIENTOS!$B:$B,$B$3,MOVIMIENTOS!$C:$C,E$5,MOVIMIENTOS!$D:$D,"Gasto") | F8: =SUMIFS(MOVIMIENTOS!$J:$J,MOVIMIENTOS!$E:$E,$A8,MOVIMIENTOS!$B:$B,$B$3,MOVIMIENTOS!$C:$C,F$5,MOVIMIENTOS!$D:$D,"Gasto") | G8: =SUMIFS(MOVIMIENTOS!$J:$J,MOVIMIENTOS!$E:$E,$A8,MOVIMIENTOS!$B:$B,$B$3,MOVIMIENTOS!$C:$C,G$5,MOVIMIENTOS!$D:$D,"Gasto") | H8: =SUMIFS(MOVIMIENTOS!$J:$J,MOVIMIENTOS!$E:$E,$A8,MOVIMIENTOS!$B:$B,$B$3,MOVIMIENTOS!$C:$C,H$5,MOVIMIENTOS!$D:$D,"Gasto") | I8: =SUMIFS(MOVIMIENTOS!$J:$J,MOVIMIENTOS!$E:$E,$A8,MOVIMIENTOS!$B:$B,$B$3,MOVIMIENTOS!$C:$C,I$5,MOVIMIENTOS!$D:$D,"Gasto") | ... M8: =SUMIFS(MOVIMIENTOS!$J:$J,MOVIMIENTOS!$E:$E,$A8,MOVIMIENTOS!$B:$B,$B$3,MOVIMIENTOS!$C:$C,M$5,MOVIMIENTOS!$D:$D,"Gasto") | N8: =SUM($B8:$M8)
A9: Impuestos y Tasas | B9: =SUMIFS(MOVIMIENTOS!$J:$J,MOVIMIENTOS!$E:$E,$A9,MOVIMIENTOS!$B:$B,$B$3,MOVIMIENTOS!$C:$C,B$5,MOVIMIENTOS!$D:$D,"Gasto") | C9: =SUMIFS(MOVIMIENTOS!$J:$J,MOVIMIENTOS!$E:$E,$A9,MOVIMIENTOS!$B:$B,$B$3,MOVIMIENTOS!$C:$C,C$5,MOVIMIENTOS!$D:$D,"Gasto") | D9: =SUMIFS(MOVIMIENTOS!$J:$J,MOVIMIENTOS!$E:$E,$A9,MOVIMIENTOS!$B:$B,$B$3,MOVIMIENTOS!$C:$C,D$5,MOVIMIENTOS!$D:$D,"Gasto") | E9: =SUMIFS(MOVIMIENTOS!$J:$J,MOVIMIENTOS!$E:$E,$A9,MOVIMIENTOS!$B:$B,$B$3,MOVIMIENTOS!$C:$C,E$5,MOVIMIENTOS!$D:$D,"Gasto") | F9: =SUMIFS(MOVIMIENTOS!$J:$J,MOVIMIENTOS!$E:$E,$A9,MOVIMIENTOS!$B:$B,$B$3,MOVIMIENTOS!$C:$C,F$5,MOVIMIENTOS!$D:$D,"Gasto") | G9: =SUMIFS(MOVIMIENTOS!$J:$J,MOVIMIENTOS!$E:$E,$A9,MOVIMIENTOS!$B:$B,$B$3,MOVIMIENTOS!$C:$C,G$5,MOVIMIENTOS!$D:$D,"Gasto") | H9: =SUMIFS(MOVIMIENTOS!$J:$J,MOVIMIENTOS!$E:$E,$A9,MOVIMIENTOS!$B:$B,$B$3,MOVIMIENTOS!$C:$C,H$5,MOVIMIENTOS!$D:$D,"Gasto") | I9: =SUMIFS(MOVIMIENTOS!$J:$J,MOVIMIENTOS!$E:$E,$A9,MOVIMIENTOS!$B:$B,$B$3,MOVIMIENTOS!$C:$C,I$5,MOVIMIENTOS!$D:$D,"Gasto") | ... M9: =SUMIFS(MOVIMIENTOS!$J:$J,MOVIMIENTOS!$E:$E,$A9,MOVIMIENTOS!$B:$B,$B$3,MOVIMIENTOS!$C:$C,M$5,MOVIMIENTOS!$D:$D,"Gasto") | N9: =SUM($B9:$M9)
A10: Supermercado | B10: =SUMIFS(MOVIMIENTOS!$J:$J,MOVIMIENTOS!$E:$E,$A10,MOVIMIENTOS!$B:$B,$B$3,MOVIMIENTOS!$C:$C,B$5,MOVIMIENTOS!$D:$D,"Gasto") | C10: =SUMIFS(MOVIMIENTOS!$J:$J,MOVIMIENTOS!$E:$E,$A10,MOVIMIENTOS!$B:$B,$B$3,MOVIMIENTOS!$C:$C,C$5,MOVIMIENTOS!$D:$D,"Gasto") | D10: =SUMIFS(MOVIMIENTOS!$J:$J,MOVIMIENTOS!$E:$E,$A10,MOVIMIENTOS!$B:$B,$B$3,MOVIMIENTOS!$C:$C,D$5,MOVIMIENTOS!$D:$D,"Gasto") | E10: =SUMIFS(MOVIMIENTOS!$J:$J,MOVIMIENTOS!$E:$E,$A10,MOVIMIENTOS!$B:$B,$B$3,MOVIMIENTOS!$C:$C,E$5,MOVIMIENTOS!$D:$D,"Gasto") | F10: =SUMIFS(MOVIMIENTOS!$J:$J,MOVIMIENTOS!$E:$E,$A10,MOVIMIENTOS!$B:$B,$B$3,MOVIMIENTOS!$C:$C,F$5,MOVIMIENTOS!$D:$D,"Gasto") | G10: =SUMIFS(MOVIMIENTOS!$J:$J,MOVIMIENTOS!$E:$E,$A10,MOVIMIENTOS!$B:$B,$B$3,MOVIMIENTOS!$C:$C,G$5,MOVIMIENTOS!$D:$D,"Gasto") | H10: =SUMIFS(MOVIMIENTOS!$J:$J,MOVIMIENTOS!$E:$E,$A10,MOVIMIENTOS!$B:$B,$B$3,MOVIMIENTOS!$C:$C,H$5,MOVIMIENTOS!$D:$D,"Gasto") | I10: =SUMIFS(MOVIMIENTOS!$J:$J,MOVIMIENTOS!$E:$E,$A10,MOVIMIENTOS!$B:$B,$B$3,MOVIMIENTOS!$C:$C,I$5,MOVIMIENTOS!$D:$D,"Gasto") | ... M10: =SUMIFS(MOVIMIENTOS!$J:$J,MOVIMIENTOS!$E:$E,$A10,MOVIMIENTOS!$B:$B,$B$3,MOVIMIENTOS!$C:$C,M$5,MOVIMIENTOS!$D:$D,"Gasto") | N10: =SUM($B10:$M10)
A11: Comida y Salidas | B11: =SUMIFS(MOVIMIENTOS!$J:$J,MOVIMIENTOS!$E:$E,$A11,MOVIMIENTOS!$B:$B,$B$3,MOVIMIENTOS!$C:$C,B$5,MOVIMIENTOS!$D:$D,"Gasto") | C11: =SUMIFS(MOVIMIENTOS!$J:$J,MOVIMIENTOS!$E:$E,$A11,MOVIMIENTOS!$B:$B,$B$3,MOVIMIENTOS!$C:$C,C$5,MOVIMIENTOS!$D:$D,"Gasto") | D11: =SUMIFS(MOVIMIENTOS!$J:$J,MOVIMIENTOS!$E:$E,$A11,MOVIMIENTOS!$B:$B,$B$3,MOVIMIENTOS!$C:$C,D$5,MOVIMIENTOS!$D:$D,"Gasto") | E11: =SUMIFS(MOVIMIENTOS!$J:$J,MOVIMIENTOS!$E:$E,$A11,MOVIMIENTOS!$B:$B,$B$3,MOVIMIENTOS!$C:$C,E$5,MOVIMIENTOS!$D:$D,"Gasto") | F11: =SUMIFS(MOVIMIENTOS!$J:$J,MOVIMIENTOS!$E:$E,$A11,MOVIMIENTOS!$B:$B,$B$3,MOVIMIENTOS!$C:$C,F$5,MOVIMIENTOS!$D:$D,"Gasto") | G11: =SUMIFS(MOVIMIENTOS!$J:$J,MOVIMIENTOS!$E:$E,$A11,MOVIMIENTOS!$B:$B,$B$3,MOVIMIENTOS!$C:$C,G$5,MOVIMIENTOS!$D:$D,"Gasto") | H11: =SUMIFS(MOVIMIENTOS!$J:$J,MOVIMIENTOS!$E:$E,$A11,MOVIMIENTOS!$B:$B,$B$3,MOVIMIENTOS!$C:$C,H$5,MOVIMIENTOS!$D:$D,"Gasto") | I11: =SUMIFS(MOVIMIENTOS!$J:$J,MOVIMIENTOS!$E:$E,$A11,MOVIMIENTOS!$B:$B,$B$3,MOVIMIENTOS!$C:$C,I$5,MOVIMIENTOS!$D:$D,"Gasto") | ... M11: =SUMIFS(MOVIMIENTOS!$J:$J,MOVIMIENTOS!$E:$E,$A11,MOVIMIENTOS!$B:$B,$B$3,MOVIMIENTOS!$C:$C,M$5,MOVIMIENTOS!$D:$D,"Gasto") | N11: =SUM($B11:$M11)
A12: Transporte | B12: =SUMIFS(MOVIMIENTOS!$J:$J,MOVIMIENTOS!$E:$E,$A12,MOVIMIENTOS!$B:$B,$B$3,MOVIMIENTOS!$C:$C,B$5,MOVIMIENTOS!$D:$D,"Gasto") | C12: =SUMIFS(MOVIMIENTOS!$J:$J,MOVIMIENTOS!$E:$E,$A12,MOVIMIENTOS!$B:$B,$B$3,MOVIMIENTOS!$C:$C,C$5,MOVIMIENTOS!$D:$D,"Gasto") | D12: =SUMIFS(MOVIMIENTOS!$J:$J,MOVIMIENTOS!$E:$E,$A12,MOVIMIENTOS!$B:$B,$B$3,MOVIMIENTOS!$C:$C,D$5,MOVIMIENTOS!$D:$D,"Gasto") | E12: =SUMIFS(MOVIMIENTOS!$J:$J,MOVIMIENTOS!$E:$E,$A12,MOVIMIENTOS!$B:$B,$B$3,MOVIMIENTOS!$C:$C,E$5,MOVIMIENTOS!$D:$D,"Gasto") | F12: =SUMIFS(MOVIMIENTOS!$J:$J,MOVIMIENTOS!$E:$E,$A12,MOVIMIENTOS!$B:$B,$B$3,MOVIMIENTOS!$C:$C,F$5,MOVIMIENTOS!$D:$D,"Gasto") | G12: =SUMIFS(MOVIMIENTOS!$J:$J,MOVIMIENTOS!$E:$E,$A12,MOVIMIENTOS!$B:$B,$B$3,MOVIMIENTOS!$C:$C,G$5,MOVIMIENTOS!$D:$D,"Gasto") | H12: =SUMIFS(MOVIMIENTOS!$J:$J,MOVIMIENTOS!$E:$E,$A12,MOVIMIENTOS!$B:$B,$B$3,MOVIMIENTOS!$C:$C,H$5,MOVIMIENTOS!$D:$D,"Gasto") | I12: =SUMIFS(MOVIMIENTOS!$J:$J,MOVIMIENTOS!$E:$E,$A12,MOVIMIENTOS!$B:$B,$B$3,MOVIMIENTOS!$C:$C,I$5,MOVIMIENTOS!$D:$D,"Gasto") | ... M12: =SUMIFS(MOVIMIENTOS!$J:$J,MOVIMIENTOS!$E:$E,$A12,MOVIMIENTOS!$B:$B,$B$3,MOVIMIENTOS!$C:$C,M$5,MOVIMIENTOS!$D:$D,"Gasto") | N12: =SUM($B12:$M12)
A13: Combustible | B13: =SUMIFS(MOVIMIENTOS!$J:$J,MOVIMIENTOS!$E:$E,$A13,MOVIMIENTOS!$B:$B,$B$3,MOVIMIENTOS!$C:$C,B$5,MOVIMIENTOS!$D:$D,"Gasto") | C13: =SUMIFS(MOVIMIENTOS!$J:$J,MOVIMIENTOS!$E:$E,$A13,MOVIMIENTOS!$B:$B,$B$3,MOVIMIENTOS!$C:$C,C$5,MOVIMIENTOS!$D:$D,"Gasto") | D13: =SUMIFS(MOVIMIENTOS!$J:$J,MOVIMIENTOS!$E:$E,$A13,MOVIMIENTOS!$B:$B,$B$3,MOVIMIENTOS!$C:$C,D$5,MOVIMIENTOS!$D:$D,"Gasto") | E13: =SUMIFS(MOVIMIENTOS!$J:$J,MOVIMIENTOS!$E:$E,$A13,MOVIMIENTOS!$B:$B,$B$3,MOVIMIENTOS!$C:$C,E$5,MOVIMIENTOS!$D:$D,"Gasto") | F13: =SUMIFS(MOVIMIENTOS!$J:$J,MOVIMIENTOS!$E:$E,$A13,MOVIMIENTOS!$B:$B,$B$3,MOVIMIENTOS!$C:$C,F$5,MOVIMIENTOS!$D:$D,"Gasto") | G13: =SUMIFS(MOVIMIENTOS!$J:$J,MOVIMIENTOS!$E:$E,$A13,MOVIMIENTOS!$B:$B,$B$3,MOVIMIENTOS!$C:$C,G$5,MOVIMIENTOS!$D:$D,"Gasto") | H13: =SUMIFS(MOVIMIENTOS!$J:$J,MOVIMIENTOS!$E:$E,$A13,MOVIMIENTOS!$B:$B,$B$3,MOVIMIENTOS!$C:$C,H$5,MOVIMIENTOS!$D:$D,"Gasto") | I13: =SUMIFS(MOVIMIENTOS!$J:$J,MOVIMIENTOS!$E:$E,$A13,MOVIMIENTOS!$B:$B,$B$3,MOVIMIENTOS!$C:$C,I$5,MOVIMIENTOS!$D:$D,"Gasto") | ... M13: =SUMIFS(MOVIMIENTOS!$J:$J,MOVIMIENTOS!$E:$E,$A13,MOVIMIENTOS!$B:$B,$B$3,MOVIMIENTOS!$C:$C,M$5,MOVIMIENTOS!$D:$D,"Gasto") | N13: =SUM($B13:$M13)
A14: Vehiculos - Mantenimiento | B14: =SUMIFS(MOVIMIENTOS!$J:$J,MOVIMIENTOS!$E:$E,$A14,MOVIMIENTOS!$B:$B,$B$3,MOVIMIENTOS!$C:$C,B$5,MOVIMIENTOS!$D:$D,"Gasto") | C14: =SUMIFS(MOVIMIENTOS!$J:$J,MOVIMIENTOS!$E:$E,$A14,MOVIMIENTOS!$B:$B,$B$3,MOVIMIENTOS!$C:$C,C$5,MOVIMIENTOS!$D:$D,"Gasto") | D14: =SUMIFS(MOVIMIENTOS!$J:$J,MOVIMIENTOS!$E:$E,$A14,MOVIMIENTOS!$B:$B,$B$3,MOVIMIENTOS!$C:$C,D$5,MOVIMIENTOS!$D:$D,"Gasto") | E14: =SUMIFS(MOVIMIENTOS!$J:$J,MOVIMIENTOS!$E:$E,$A14,MOVIMIENTOS!$B:$B,$B$3,MOVIMIENTOS!$C:$C,E$5,MOVIMIENTOS!$D:$D,"Gasto") | F14: =SUMIFS(MOVIMIENTOS!$J:$J,MOVIMIENTOS!$E:$E,$A14,MOVIMIENTOS!$B:$B,$B$3,MOVIMIENTOS!$C:$C,F$5,MOVIMIENTOS!$D:$D,"Gasto") | G14: =SUMIFS(MOVIMIENTOS!$J:$J,MOVIMIENTOS!$E:$E,$A14,MOVIMIENTOS!$B:$B,$B$3,MOVIMIENTOS!$C:$C,G$5,MOVIMIENTOS!$D:$D,"Gasto") | H14: =SUMIFS(MOVIMIENTOS!$J:$J,MOVIMIENTOS!$E:$E,$A14,MOVIMIENTOS!$B:$B,$B$3,MOVIMIENTOS!$C:$C,H$5,MOVIMIENTOS!$D:$D,"Gasto") | I14: =SUMIFS(MOVIMIENTOS!$J:$J,MOVIMIENTOS!$E:$E,$A14,MOVIMIENTOS!$B:$B,$B$3,MOVIMIENTOS!$C:$C,I$5,MOVIMIENTOS!$D:$D,"Gasto") | ... M14: =SUMIFS(MOVIMIENTOS!$J:$J,MOVIMIENTOS!$E:$E,$A14,MOVIMIENTOS!$B:$B,$B$3,MOVIMIENTOS!$C:$C,M$5,MOVIMIENTOS!$D:$D,"Gasto") | N14: =SUM($B14:$M14)
A15: Seguros | B15: =SUMIFS(MOVIMIENTOS!$J:$J,MOVIMIENTOS!$E:$E,$A15,MOVIMIENTOS!$B:$B,$B$3,MOVIMIENTOS!$C:$C,B$5,MOVIMIENTOS!$D:$D,"Gasto") | C15: =SUMIFS(MOVIMIENTOS!$J:$J,MOVIMIENTOS!$E:$E,$A15,MOVIMIENTOS!$B:$B,$B$3,MOVIMIENTOS!$C:$C,C$5,MOVIMIENTOS!$D:$D,"Gasto") | D15: =SUMIFS(MOVIMIENTOS!$J:$J,MOVIMIENTOS!$E:$E,$A15,MOVIMIENTOS!$B:$B,$B$3,MOVIMIENTOS!$C:$C,D$5,MOVIMIENTOS!$D:$D,"Gasto") | E15: =SUMIFS(MOVIMIENTOS!$J:$J,MOVIMIENTOS!$E:$E,$A15,MOVIMIENTOS!$B:$B,$B$3,MOVIMIENTOS!$C:$C,E$5,MOVIMIENTOS!$D:$D,"Gasto") | F15: =SUMIFS(MOVIMIENTOS!$J:$J,MOVIMIENTOS!$E:$E,$A15,MOVIMIENTOS!$B:$B,$B$3,MOVIMIENTOS!$C:$C,F$5,MOVIMIENTOS!$D:$D,"Gasto") | G15: =SUMIFS(MOVIMIENTOS!$J:$J,MOVIMIENTOS!$E:$E,$A15,MOVIMIENTOS!$B:$B,$B$3,MOVIMIENTOS!$C:$C,G$5,MOVIMIENTOS!$D:$D,"Gasto") | H15: =SUMIFS(MOVIMIENTOS!$J:$J,MOVIMIENTOS!$E:$E,$A15,MOVIMIENTOS!$B:$B,$B$3,MOVIMIENTOS!$C:$C,H$5,MOVIMIENTOS!$D:$D,"Gasto") | I15: =SUMIFS(MOVIMIENTOS!$J:$J,MOVIMIENTOS!$E:$E,$A15,MOVIMIENTOS!$B:$B,$B$3,MOVIMIENTOS!$C:$C,I$5,MOVIMIENTOS!$D:$D,"Gasto") | ... M15: =SUMIFS(MOVIMIENTOS!$J:$J,MOVIMIENTOS!$E:$E,$A15,MOVIMIENTOS!$B:$B,$B$3,MOVIMIENTOS!$C:$C,M$5,MOVIMIENTOS!$D:$D,"Gasto") | N15: =SUM($B15:$M15)
A16: Salud | B16: =SUMIFS(MOVIMIENTOS!$J:$J,MOVIMIENTOS!$E:$E,$A16,MOVIMIENTOS!$B:$B,$B$3,MOVIMIENTOS!$C:$C,B$5,MOVIMIENTOS!$D:$D,"Gasto") | C16: =SUMIFS(MOVIMIENTOS!$J:$J,MOVIMIENTOS!$E:$E,$A16,MOVIMIENTOS!$B:$B,$B$3,MOVIMIENTOS!$C:$C,C$5,MOVIMIENTOS!$D:$D,"Gasto") | D16: =SUMIFS(MOVIMIENTOS!$J:$J,MOVIMIENTOS!$E:$E,$A16,MOVIMIENTOS!$B:$B,$B$3,MOVIMIENTOS!$C:$C,D$5,MOVIMIENTOS!$D:$D,"Gasto") | E16: =SUMIFS(MOVIMIENTOS!$J:$J,MOVIMIENTOS!$E:$E,$A16,MOVIMIENTOS!$B:$B,$B$3,MOVIMIENTOS!$C:$C,E$5,MOVIMIENTOS!$D:$D,"Gasto") | F16: =SUMIFS(MOVIMIENTOS!$J:$J,MOVIMIENTOS!$E:$E,$A16,MOVIMIENTOS!$B:$B,$B$3,MOVIMIENTOS!$C:$C,F$5,MOVIMIENTOS!$D:$D,"Gasto") | G16: =SUMIFS(MOVIMIENTOS!$J:$J,MOVIMIENTOS!$E:$E,$A16,MOVIMIENTOS!$B:$B,$B$3,MOVIMIENTOS!$C:$C,G$5,MOVIMIENTOS!$D:$D,"Gasto") | H16: =SUMIFS(MOVIMIENTOS!$J:$J,MOVIMIENTOS!$E:$E,$A16,MOVIMIENTOS!$B:$B,$B$3,MOVIMIENTOS!$C:$C,H$5,MOVIMIENTOS!$D:$D,"Gasto") | I16: =SUMIFS(MOVIMIENTOS!$J:$J,MOVIMIENTOS!$E:$E,$A16,MOVIMIENTOS!$B:$B,$B$3,MOVIMIENTOS!$C:$C,I$5,MOVIMIENTOS!$D:$D,"Gasto") | ... M16: =SUMIFS(MOVIMIENTOS!$J:$J,MOVIMIENTOS!$E:$E,$A16,MOVIMIENTOS!$B:$B,$B$3,MOVIMIENTOS!$C:$C,M$5,MOVIMIENTOS!$D:$D,"Gasto") | N16: =SUM($B16:$M16)
A17: Educacion | B17: =SUMIFS(MOVIMIENTOS!$J:$J,MOVIMIENTOS!$E:$E,$A17,MOVIMIENTOS!$B:$B,$B$3,MOVIMIENTOS!$C:$C,B$5,MOVIMIENTOS!$D:$D,"Gasto") | C17: =SUMIFS(MOVIMIENTOS!$J:$J,MOVIMIENTOS!$E:$E,$A17,MOVIMIENTOS!$B:$B,$B$3,MOVIMIENTOS!$C:$C,C$5,MOVIMIENTOS!$D:$D,"Gasto") | D17: =SUMIFS(MOVIMIENTOS!$J:$J,MOVIMIENTOS!$E:$E,$A17,MOVIMIENTOS!$B:$B,$B$3,MOVIMIENTOS!$C:$C,D$5,MOVIMIENTOS!$D:$D,"Gasto") | E17: =SUMIFS(MOVIMIENTOS!$J:$J,MOVIMIENTOS!$E:$E,$A17,MOVIMIENTOS!$B:$B,$B$3,MOVIMIENTOS!$C:$C,E$5,MOVIMIENTOS!$D:$D,"Gasto") | F17: =SUMIFS(MOVIMIENTOS!$J:$J,MOVIMIENTOS!$E:$E,$A17,MOVIMIENTOS!$B:$B,$B$3,MOVIMIENTOS!$C:$C,F$5,MOVIMIENTOS!$D:$D,"Gasto") | G17: =SUMIFS(MOVIMIENTOS!$J:$J,MOVIMIENTOS!$E:$E,$A17,MOVIMIENTOS!$B:$B,$B$3,MOVIMIENTOS!$C:$C,G$5,MOVIMIENTOS!$D:$D,"Gasto") | H17: =SUMIFS(MOVIMIENTOS!$J:$J,MOVIMIENTOS!$E:$E,$A17,MOVIMIENTOS!$B:$B,$B$3,MOVIMIENTOS!$C:$C,H$5,MOVIMIENTOS!$D:$D,"Gasto") | I17: =SUMIFS(MOVIMIENTOS!$J:$J,MOVIMIENTOS!$E:$E,$A17,MOVIMIENTOS!$B:$B,$B$3,MOVIMIENTOS!$C:$C,I$5,MOVIMIENTOS!$D:$D,"Gasto") | ... M17: =SUMIFS(MOVIMIENTOS!$J:$J,MOVIMIENTOS!$E:$E,$A17,MOVIMIENTOS!$B:$B,$B$3,MOVIMIENTOS!$C:$C,M$5,MOVIMIENTOS!$D:$D,"Gasto") | N17: =SUM($B17:$M17)
A18: Indumentaria | B18: =SUMIFS(MOVIMIENTOS!$J:$J,MOVIMIENTOS!$E:$E,$A18,MOVIMIENTOS!$B:$B,$B$3,MOVIMIENTOS!$C:$C,B$5,MOVIMIENTOS!$D:$D,"Gasto") | C18: =SUMIFS(MOVIMIENTOS!$J:$J,MOVIMIENTOS!$E:$E,$A18,MOVIMIENTOS!$B:$B,$B$3,MOVIMIENTOS!$C:$C,C$5,MOVIMIENTOS!$D:$D,"Gasto") | D18: =SUMIFS(MOVIMIENTOS!$J:$J,MOVIMIENTOS!$E:$E,$A18,MOVIMIENTOS!$B:$B,$B$3,MOVIMIENTOS!$C:$C,D$5,MOVIMIENTOS!$D:$D,"Gasto") | E18: =SUMIFS(MOVIMIENTOS!$J:$J,MOVIMIENTOS!$E:$E,$A18,MOVIMIENTOS!$B:$B,$B$3,MOVIMIENTOS!$C:$C,E$5,MOVIMIENTOS!$D:$D,"Gasto") | F18: =SUMIFS(MOVIMIENTOS!$J:$J,MOVIMIENTOS!$E:$E,$A18,MOVIMIENTOS!$B:$B,$B$3,MOVIMIENTOS!$C:$C,F$5,MOVIMIENTOS!$D:$D,"Gasto") | G18: =SUMIFS(MOVIMIENTOS!$J:$J,MOVIMIENTOS!$E:$E,$A18,MOVIMIENTOS!$B:$B,$B$3,MOVIMIENTOS!$C:$C,G$5,MOVIMIENTOS!$D:$D,"Gasto") | H18: =SUMIFS(MOVIMIENTOS!$J:$J,MOVIMIENTOS!$E:$E,$A18,MOVIMIENTOS!$B:$B,$B$3,MOVIMIENTOS!$C:$C,H$5,MOVIMIENTOS!$D:$D,"Gasto") | I18: =SUMIFS(MOVIMIENTOS!$J:$J,MOVIMIENTOS!$E:$E,$A18,MOVIMIENTOS!$B:$B,$B$3,MOVIMIENTOS!$C:$C,I$5,MOVIMIENTOS!$D:$D,"Gasto") | ... M18: =SUMIFS(MOVIMIENTOS!$J:$J,MOVIMIENTOS!$E:$E,$A18,MOVIMIENTOS!$B:$B,$B$3,MOVIMIENTOS!$C:$C,M$5,MOVIMIENTOS!$D:$D,"Gasto") | N18: =SUM($B18:$M18)
... A35: Gastos Varios | B35: =SUMIFS(MOVIMIENTOS!$J:$J,MOVIMIENTOS!$E:$E,$A35,MOVIMIENTOS!$B:$B,$B$3,MOVIMIENTOS!$C:$C,B$5,MOVIMIENTOS!$D:$D,"Gasto") | C35: =SUMIFS(MOVIMIENTOS!$J:$J,MOVIMIENTOS!$E:$E,$A35,MOVIMIENTOS!$B:$B,$B$3,MOVIMIENTOS!$C:$C,C$5,MOVIMIENTOS!$D:$D,"Gasto") | D35: =SUMIFS(MOVIMIENTOS!$J:$J,MOVIMIENTOS!$E:$E,$A35,MOVIMIENTOS!$B:$B,$B$3,MOVIMIENTOS!$C:$C,D$5,MOVIMIENTOS!$D:$D,"Gasto") | E35: =SUMIFS(MOVIMIENTOS!$J:$J,MOVIMIENTOS!$E:$E,$A35,MOVIMIENTOS!$B:$B,$B$3,MOVIMIENTOS!$C:$C,E$5,MOVIMIENTOS!$D:$D,"Gasto") | F35: =SUMIFS(MOVIMIENTOS!$J:$J,MOVIMIENTOS!$E:$E,$A35,MOVIMIENTOS!$B:$B,$B$3,MOVIMIENTOS!$C:$C,F$5,MOVIMIENTOS!$D:$D,"Gasto") | G35: =SUMIFS(MOVIMIENTOS!$J:$J,MOVIMIENTOS!$E:$E,$A35,MOVIMIENTOS!$B:$B,$B$3,MOVIMIENTOS!$C:$C,G$5,MOVIMIENTOS!$D:$D,"Gasto") | H35: =SUMIFS(MOVIMIENTOS!$J:$J,MOVIMIENTOS!$E:$E,$A35,MOVIMIENTOS!$B:$B,$B$3,MOVIMIENTOS!$C:$C,H$5,MOVIMIENTOS!$D:$D,"Gasto") | I35: =SUMIFS(MOVIMIENTOS!$J:$J,MOVIMIENTOS!$E:$E,$A35,MOVIMIENTOS!$B:$B,$B$3,MOVIMIENTOS!$C:$C,I$5,MOVIMIENTOS!$D:$D,"Gasto") | ... M35: =SUMIFS(MOVIMIENTOS!$J:$J,MOVIMIENTOS!$E:$E,$A35,MOVIMIENTOS!$B:$B,$B$3,MOVIMIENTOS!$C:$C,M$5,MOVIMIENTOS!$D:$D,"Gasto") | N35: =SUM($B35:$M35)
A36: TOTAL GASTOS | B36: =SUM(B7:B35) | C36: =SUM(C7:C35) | D36: =SUM(D7:D35) | E36: =SUM(E7:E35) | F36: =SUM(F7:F35) | G36: =SUM(G7:G35) | H36: =SUM(H7:H35) | I36: =SUM(I7:I35) | ... N36: =SUM(N7:N35)
A38: INGRESOS
A39: CATEGORIA | B39: Enero | C39: Febrero | D39: Marzo | E39: Abril | F39: Mayo | G39: Junio | H39: Julio | I39: Agosto | J39: Septiembre | K39: Octubre | L39: Noviembre | M39: Diciembre | N39: TOTAL AÑO
A40: Ventas | B40: =SUMIFS(MOVIMIENTOS!$J:$J,MOVIMIENTOS!$E:$E,$A40,MOVIMIENTOS!$B:$B,$B$3,MOVIMIENTOS!$C:$C,B$5,MOVIMIENTOS!$D:$D,"Ingreso") | C40: =SUMIFS(MOVIMIENTOS!$J:$J,MOVIMIENTOS!$E:$E,$A40,MOVIMIENTOS!$B:$B,$B$3,MOVIMIENTOS!$C:$C,C$5,MOVIMIENTOS!$D:$D,"Ingreso") | D40: =SUMIFS(MOVIMIENTOS!$J:$J,MOVIMIENTOS!$E:$E,$A40,MOVIMIENTOS!$B:$B,$B$3,MOVIMIENTOS!$C:$C,D$5,MOVIMIENTOS!$D:$D,"Ingreso") | E40: =SUMIFS(MOVIMIENTOS!$J:$J,MOVIMIENTOS!$E:$E,$A40,MOVIMIENTOS!$B:$B,$B$3,MOVIMIENTOS!$C:$C,E$5,MOVIMIENTOS!$D:$D,"Ingreso") | F40: =SUMIFS(MOVIMIENTOS!$J:$J,MOVIMIENTOS!$E:$E,$A40,MOVIMIENTOS!$B:$B,$B$3,MOVIMIENTOS!$C:$C,F$5,MOVIMIENTOS!$D:$D,"Ingreso") | G40: =SUMIFS(MOVIMIENTOS!$J:$J,MOVIMIENTOS!$E:$E,$A40,MOVIMIENTOS!$B:$B,$B$3,MOVIMIENTOS!$C:$C,G$5,MOVIMIENTOS!$D:$D,"Ingreso") | H40: =SUMIFS(MOVIMIENTOS!$J:$J,MOVIMIENTOS!$E:$E,$A40,MOVIMIENTOS!$B:$B,$B$3,MOVIMIENTOS!$C:$C,H$5,MOVIMIENTOS!$D:$D,"Ingreso") | I40: =SUMIFS(MOVIMIENTOS!$J:$J,MOVIMIENTOS!$E:$E,$A40,MOVIMIENTOS!$B:$B,$B$3,MOVIMIENTOS!$C:$C,I$5,MOVIMIENTOS!$D:$D,"Ingreso") | ... M40: =SUMIFS(MOVIMIENTOS!$J:$J,MOVIMIENTOS!$E:$E,$A40,MOVIMIENTOS!$B:$B,$B$3,MOVIMIENTOS!$C:$C,M$5,MOVIMIENTOS!$D:$D,"Ingreso") | N40: =SUM($B40:$M40)
A41: Cobranza de Cuotas | B41: =SUMIFS(MOVIMIENTOS!$J:$J,MOVIMIENTOS!$E:$E,$A41,MOVIMIENTOS!$B:$B,$B$3,MOVIMIENTOS!$C:$C,B$5,MOVIMIENTOS!$D:$D,"Ingreso") | C41: =SUMIFS(MOVIMIENTOS!$J:$J,MOVIMIENTOS!$E:$E,$A41,MOVIMIENTOS!$B:$B,$B$3,MOVIMIENTOS!$C:$C,C$5,MOVIMIENTOS!$D:$D,"Ingreso") | D41: =SUMIFS(MOVIMIENTOS!$J:$J,MOVIMIENTOS!$E:$E,$A41,MOVIMIENTOS!$B:$B,$B$3,MOVIMIENTOS!$C:$C,D$5,MOVIMIENTOS!$D:$D,"Ingreso") | E41: =SUMIFS(MOVIMIENTOS!$J:$J,MOVIMIENTOS!$E:$E,$A41,MOVIMIENTOS!$B:$B,$B$3,MOVIMIENTOS!$C:$C,E$5,MOVIMIENTOS!$D:$D,"Ingreso") | F41: =SUMIFS(MOVIMIENTOS!$J:$J,MOVIMIENTOS!$E:$E,$A41,MOVIMIENTOS!$B:$B,$B$3,MOVIMIENTOS!$C:$C,F$5,MOVIMIENTOS!$D:$D,"Ingreso") | G41: =SUMIFS(MOVIMIENTOS!$J:$J,MOVIMIENTOS!$E:$E,$A41,MOVIMIENTOS!$B:$B,$B$3,MOVIMIENTOS!$C:$C,G$5,MOVIMIENTOS!$D:$D,"Ingreso") | H41: =SUMIFS(MOVIMIENTOS!$J:$J,MOVIMIENTOS!$E:$E,$A41,MOVIMIENTOS!$B:$B,$B$3,MOVIMIENTOS!$C:$C,H$5,MOVIMIENTOS!$D:$D,"Ingreso") | I41: =SUMIFS(MOVIMIENTOS!$J:$J,MOVIMIENTOS!$E:$E,$A41,MOVIMIENTOS!$B:$B,$B$3,MOVIMIENTOS!$C:$C,I$5,MOVIMIENTOS!$D:$D,"Ingreso") | ... M41: =SUMIFS(MOVIMIENTOS!$J:$J,MOVIMIENTOS!$E:$E,$A41,MOVIMIENTOS!$B:$B,$B$3,MOVIMIENTOS!$C:$C,M$5,MOVIMIENTOS!$D:$D,"Ingreso") | N41: =SUM($B41:$M41)
A42: Alquileres Cobrados | B42: =SUMIFS(MOVIMIENTOS!$J:$J,MOVIMIENTOS!$E:$E,$A42,MOVIMIENTOS!$B:$B,$B$3,MOVIMIENTOS!$C:$C,B$5,MOVIMIENTOS!$D:$D,"Ingreso") | C42: =SUMIFS(MOVIMIENTOS!$J:$J,MOVIMIENTOS!$E:$E,$A42,MOVIMIENTOS!$B:$B,$B$3,MOVIMIENTOS!$C:$C,C$5,MOVIMIENTOS!$D:$D,"Ingreso") | D42: =SUMIFS(MOVIMIENTOS!$J:$J,MOVIMIENTOS!$E:$E,$A42,MOVIMIENTOS!$B:$B,$B$3,MOVIMIENTOS!$C:$C,D$5,MOVIMIENTOS!$D:$D,"Ingreso") | E42: =SUMIFS(MOVIMIENTOS!$J:$J,MOVIMIENTOS!$E:$E,$A42,MOVIMIENTOS!$B:$B,$B$3,MOVIMIENTOS!$C:$C,E$5,MOVIMIENTOS!$D:$D,"Ingreso") | F42: =SUMIFS(MOVIMIENTOS!$J:$J,MOVIMIENTOS!$E:$E,$A42,MOVIMIENTOS!$B:$B,$B$3,MOVIMIENTOS!$C:$C,F$5,MOVIMIENTOS!$D:$D,"Ingreso") | G42: =SUMIFS(MOVIMIENTOS!$J:$J,MOVIMIENTOS!$E:$E,$A42,MOVIMIENTOS!$B:$B,$B$3,MOVIMIENTOS!$C:$C,G$5,MOVIMIENTOS!$D:$D,"Ingreso") | H42: =SUMIFS(MOVIMIENTOS!$J:$J,MOVIMIENTOS!$E:$E,$A42,MOVIMIENTOS!$B:$B,$B$3,MOVIMIENTOS!$C:$C,H$5,MOVIMIENTOS!$D:$D,"Ingreso") | I42: =SUMIFS(MOVIMIENTOS!$J:$J,MOVIMIENTOS!$E:$E,$A42,MOVIMIENTOS!$B:$B,$B$3,MOVIMIENTOS!$C:$C,I$5,MOVIMIENTOS!$D:$D,"Ingreso") | ... M42: =SUMIFS(MOVIMIENTOS!$J:$J,MOVIMIENTOS!$E:$E,$A42,MOVIMIENTOS!$B:$B,$B$3,MOVIMIENTOS!$C:$C,M$5,MOVIMIENTOS!$D:$D,"Ingreso") | N42: =SUM($B42:$M42)
A43: Intereses Ganados | B43: =SUMIFS(MOVIMIENTOS!$J:$J,MOVIMIENTOS!$E:$E,$A43,MOVIMIENTOS!$B:$B,$B$3,MOVIMIENTOS!$C:$C,B$5,MOVIMIENTOS!$D:$D,"Ingreso") | C43: =SUMIFS(MOVIMIENTOS!$J:$J,MOVIMIENTOS!$E:$E,$A43,MOVIMIENTOS!$B:$B,$B$3,MOVIMIENTOS!$C:$C,C$5,MOVIMIENTOS!$D:$D,"Ingreso") | D43: =SUMIFS(MOVIMIENTOS!$J:$J,MOVIMIENTOS!$E:$E,$A43,MOVIMIENTOS!$B:$B,$B$3,MOVIMIENTOS!$C:$C,D$5,MOVIMIENTOS!$D:$D,"Ingreso") | E43: =SUMIFS(MOVIMIENTOS!$J:$J,MOVIMIENTOS!$E:$E,$A43,MOVIMIENTOS!$B:$B,$B$3,MOVIMIENTOS!$C:$C,E$5,MOVIMIENTOS!$D:$D,"Ingreso") | F43: =SUMIFS(MOVIMIENTOS!$J:$J,MOVIMIENTOS!$E:$E,$A43,MOVIMIENTOS!$B:$B,$B$3,MOVIMIENTOS!$C:$C,F$5,MOVIMIENTOS!$D:$D,"Ingreso") | G43: =SUMIFS(MOVIMIENTOS!$J:$J,MOVIMIENTOS!$E:$E,$A43,MOVIMIENTOS!$B:$B,$B$3,MOVIMIENTOS!$C:$C,G$5,MOVIMIENTOS!$D:$D,"Ingreso") | H43: =SUMIFS(MOVIMIENTOS!$J:$J,MOVIMIENTOS!$E:$E,$A43,MOVIMIENTOS!$B:$B,$B$3,MOVIMIENTOS!$C:$C,H$5,MOVIMIENTOS!$D:$D,"Ingreso") | I43: =SUMIFS(MOVIMIENTOS!$J:$J,MOVIMIENTOS!$E:$E,$A43,MOVIMIENTOS!$B:$B,$B$3,MOVIMIENTOS!$C:$C,I$5,MOVIMIENTOS!$D:$D,"Ingreso") | ... M43: =SUMIFS(MOVIMIENTOS!$J:$J,MOVIMIENTOS!$E:$E,$A43,MOVIMIENTOS!$B:$B,$B$3,MOVIMIENTOS!$C:$C,M$5,MOVIMIENTOS!$D:$D,"Ingreso") | N43: =SUM($B43:$M43)
A44: Sueldo | B44: =SUMIFS(MOVIMIENTOS!$J:$J,MOVIMIENTOS!$E:$E,$A44,MOVIMIENTOS!$B:$B,$B$3,MOVIMIENTOS!$C:$C,B$5,MOVIMIENTOS!$D:$D,"Ingreso") | C44: =SUMIFS(MOVIMIENTOS!$J:$J,MOVIMIENTOS!$E:$E,$A44,MOVIMIENTOS!$B:$B,$B$3,MOVIMIENTOS!$C:$C,C$5,MOVIMIENTOS!$D:$D,"Ingreso") | D44: =SUMIFS(MOVIMIENTOS!$J:$J,MOVIMIENTOS!$E:$E,$A44,MOVIMIENTOS!$B:$B,$B$3,MOVIMIENTOS!$C:$C,D$5,MOVIMIENTOS!$D:$D,"Ingreso") | E44: =SUMIFS(MOVIMIENTOS!$J:$J,MOVIMIENTOS!$E:$E,$A44,MOVIMIENTOS!$B:$B,$B$3,MOVIMIENTOS!$C:$C,E$5,MOVIMIENTOS!$D:$D,"Ingreso") | F44: =SUMIFS(MOVIMIENTOS!$J:$J,MOVIMIENTOS!$E:$E,$A44,MOVIMIENTOS!$B:$B,$B$3,MOVIMIENTOS!$C:$C,F$5,MOVIMIENTOS!$D:$D,"Ingreso") | G44: =SUMIFS(MOVIMIENTOS!$J:$J,MOVIMIENTOS!$E:$E,$A44,MOVIMIENTOS!$B:$B,$B$3,MOVIMIENTOS!$C:$C,G$5,MOVIMIENTOS!$D:$D,"Ingreso") | H44: =SUMIFS(MOVIMIENTOS!$J:$J,MOVIMIENTOS!$E:$E,$A44,MOVIMIENTOS!$B:$B,$B$3,MOVIMIENTOS!$C:$C,H$5,MOVIMIENTOS!$D:$D,"Ingreso") | I44: =SUMIFS(MOVIMIENTOS!$J:$J,MOVIMIENTOS!$E:$E,$A44,MOVIMIENTOS!$B:$B,$B$3,MOVIMIENTOS!$C:$C,I$5,MOVIMIENTOS!$D:$D,"Ingreso") | ... M44: =SUMIFS(MOVIMIENTOS!$J:$J,MOVIMIENTOS!$E:$E,$A44,MOVIMIENTOS!$B:$B,$B$3,MOVIMIENTOS!$C:$C,M$5,MOVIMIENTOS!$D:$D,"Ingreso") | N44: =SUM($B44:$M44)
A45: Honorarios | B45: =SUMIFS(MOVIMIENTOS!$J:$J,MOVIMIENTOS!$E:$E,$A45,MOVIMIENTOS!$B:$B,$B$3,MOVIMIENTOS!$C:$C,B$5,MOVIMIENTOS!$D:$D,"Ingreso") | C45: =SUMIFS(MOVIMIENTOS!$J:$J,MOVIMIENTOS!$E:$E,$A45,MOVIMIENTOS!$B:$B,$B$3,MOVIMIENTOS!$C:$C,C$5,MOVIMIENTOS!$D:$D,"Ingreso") | D45: =SUMIFS(MOVIMIENTOS!$J:$J,MOVIMIENTOS!$E:$E,$A45,MOVIMIENTOS!$B:$B,$B$3,MOVIMIENTOS!$C:$C,D$5,MOVIMIENTOS!$D:$D,"Ingreso") | E45: =SUMIFS(MOVIMIENTOS!$J:$J,MOVIMIENTOS!$E:$E,$A45,MOVIMIENTOS!$B:$B,$B$3,MOVIMIENTOS!$C:$C,E$5,MOVIMIENTOS!$D:$D,"Ingreso") | F45: =SUMIFS(MOVIMIENTOS!$J:$J,MOVIMIENTOS!$E:$E,$A45,MOVIMIENTOS!$B:$B,$B$3,MOVIMIENTOS!$C:$C,F$5,MOVIMIENTOS!$D:$D,"Ingreso") | G45: =SUMIFS(MOVIMIENTOS!$J:$J,MOVIMIENTOS!$E:$E,$A45,MOVIMIENTOS!$B:$B,$B$3,MOVIMIENTOS!$C:$C,G$5,MOVIMIENTOS!$D:$D,"Ingreso") | H45: =SUMIFS(MOVIMIENTOS!$J:$J,MOVIMIENTOS!$E:$E,$A45,MOVIMIENTOS!$B:$B,$B$3,MOVIMIENTOS!$C:$C,H$5,MOVIMIENTOS!$D:$D,"Ingreso") | I45: =SUMIFS(MOVIMIENTOS!$J:$J,MOVIMIENTOS!$E:$E,$A45,MOVIMIENTOS!$B:$B,$B$3,MOVIMIENTOS!$C:$C,I$5,MOVIMIENTOS!$D:$D,"Ingreso") | ... M45: =SUMIFS(MOVIMIENTOS!$J:$J,MOVIMIENTOS!$E:$E,$A45,MOVIMIENTOS!$B:$B,$B$3,MOVIMIENTOS!$C:$C,M$5,MOVIMIENTOS!$D:$D,"Ingreso") | N45: =SUM($B45:$M45)
A46: Devoluciones | B46: =SUMIFS(MOVIMIENTOS!$J:$J,MOVIMIENTOS!$E:$E,$A46,MOVIMIENTOS!$B:$B,$B$3,MOVIMIENTOS!$C:$C,B$5,MOVIMIENTOS!$D:$D,"Ingreso") | C46: =SUMIFS(MOVIMIENTOS!$J:$J,MOVIMIENTOS!$E:$E,$A46,MOVIMIENTOS!$B:$B,$B$3,MOVIMIENTOS!$C:$C,C$5,MOVIMIENTOS!$D:$D,"Ingreso") | D46: =SUMIFS(MOVIMIENTOS!$J:$J,MOVIMIENTOS!$E:$E,$A46,MOVIMIENTOS!$B:$B,$B$3,MOVIMIENTOS!$C:$C,D$5,MOVIMIENTOS!$D:$D,"Ingreso") | E46: =SUMIFS(MOVIMIENTOS!$J:$J,MOVIMIENTOS!$E:$E,$A46,MOVIMIENTOS!$B:$B,$B$3,MOVIMIENTOS!$C:$C,E$5,MOVIMIENTOS!$D:$D,"Ingreso") | F46: =SUMIFS(MOVIMIENTOS!$J:$J,MOVIMIENTOS!$E:$E,$A46,MOVIMIENTOS!$B:$B,$B$3,MOVIMIENTOS!$C:$C,F$5,MOVIMIENTOS!$D:$D,"Ingreso") | G46: =SUMIFS(MOVIMIENTOS!$J:$J,MOVIMIENTOS!$E:$E,$A46,MOVIMIENTOS!$B:$B,$B$3,MOVIMIENTOS!$C:$C,G$5,MOVIMIENTOS!$D:$D,"Ingreso") | H46: =SUMIFS(MOVIMIENTOS!$J:$J,MOVIMIENTOS!$E:$E,$A46,MOVIMIENTOS!$B:$B,$B$3,MOVIMIENTOS!$C:$C,H$5,MOVIMIENTOS!$D:$D,"Ingreso") | I46: =SUMIFS(MOVIMIENTOS!$J:$J,MOVIMIENTOS!$E:$E,$A46,MOVIMIENTOS!$B:$B,$B$3,MOVIMIENTOS!$C:$C,I$5,MOVIMIENTOS!$D:$D,"Ingreso") | ... M46: =SUMIFS(MOVIMIENTOS!$J:$J,MOVIMIENTOS!$E:$E,$A46,MOVIMIENTOS!$B:$B,$B$3,MOVIMIENTOS!$C:$C,M$5,MOVIMIENTOS!$D:$D,"Ingreso") | N46: =SUM($B46:$M46)
A47: Aportes de Socios | B47: =SUMIFS(MOVIMIENTOS!$J:$J,MOVIMIENTOS!$E:$E,$A47,MOVIMIENTOS!$B:$B,$B$3,MOVIMIENTOS!$C:$C,B$5,MOVIMIENTOS!$D:$D,"Ingreso") | C47: =SUMIFS(MOVIMIENTOS!$J:$J,MOVIMIENTOS!$E:$E,$A47,MOVIMIENTOS!$B:$B,$B$3,MOVIMIENTOS!$C:$C,C$5,MOVIMIENTOS!$D:$D,"Ingreso") | D47: =SUMIFS(MOVIMIENTOS!$J:$J,MOVIMIENTOS!$E:$E,$A47,MOVIMIENTOS!$B:$B,$B$3,MOVIMIENTOS!$C:$C,D$5,MOVIMIENTOS!$D:$D,"Ingreso") | E47: =SUMIFS(MOVIMIENTOS!$J:$J,MOVIMIENTOS!$E:$E,$A47,MOVIMIENTOS!$B:$B,$B$3,MOVIMIENTOS!$C:$C,E$5,MOVIMIENTOS!$D:$D,"Ingreso") | F47: =SUMIFS(MOVIMIENTOS!$J:$J,MOVIMIENTOS!$E:$E,$A47,MOVIMIENTOS!$B:$B,$B$3,MOVIMIENTOS!$C:$C,F$5,MOVIMIENTOS!$D:$D,"Ingreso") | G47: =SUMIFS(MOVIMIENTOS!$J:$J,MOVIMIENTOS!$E:$E,$A47,MOVIMIENTOS!$B:$B,$B$3,MOVIMIENTOS!$C:$C,G$5,MOVIMIENTOS!$D:$D,"Ingreso") | H47: =SUMIFS(MOVIMIENTOS!$J:$J,MOVIMIENTOS!$E:$E,$A47,MOVIMIENTOS!$B:$B,$B$3,MOVIMIENTOS!$C:$C,H$5,MOVIMIENTOS!$D:$D,"Ingreso") | I47: =SUMIFS(MOVIMIENTOS!$J:$J,MOVIMIENTOS!$E:$E,$A47,MOVIMIENTOS!$B:$B,$B$3,MOVIMIENTOS!$C:$C,I$5,MOVIMIENTOS!$D:$D,"Ingreso") | ... M47: =SUMIFS(MOVIMIENTOS!$J:$J,MOVIMIENTOS!$E:$E,$A47,MOVIMIENTOS!$B:$B,$B$3,MOVIMIENTOS!$C:$C,M$5,MOVIMIENTOS!$D:$D,"Ingreso") | N47: =SUM($B47:$M47)
A48: Otros Ingresos | B48: =SUMIFS(MOVIMIENTOS!$J:$J,MOVIMIENTOS!$E:$E,$A48,MOVIMIENTOS!$B:$B,$B$3,MOVIMIENTOS!$C:$C,B$5,MOVIMIENTOS!$D:$D,"Ingreso") | C48: =SUMIFS(MOVIMIENTOS!$J:$J,MOVIMIENTOS!$E:$E,$A48,MOVIMIENTOS!$B:$B,$B$3,MOVIMIENTOS!$C:$C,C$5,MOVIMIENTOS!$D:$D,"Ingreso") | D48: =SUMIFS(MOVIMIENTOS!$J:$J,MOVIMIENTOS!$E:$E,$A48,MOVIMIENTOS!$B:$B,$B$3,MOVIMIENTOS!$C:$C,D$5,MOVIMIENTOS!$D:$D,"Ingreso") | E48: =SUMIFS(MOVIMIENTOS!$J:$J,MOVIMIENTOS!$E:$E,$A48,MOVIMIENTOS!$B:$B,$B$3,MOVIMIENTOS!$C:$C,E$5,MOVIMIENTOS!$D:$D,"Ingreso") | F48: =SUMIFS(MOVIMIENTOS!$J:$J,MOVIMIENTOS!$E:$E,$A48,MOVIMIENTOS!$B:$B,$B$3,MOVIMIENTOS!$C:$C,F$5,MOVIMIENTOS!$D:$D,"Ingreso") | G48: =SUMIFS(MOVIMIENTOS!$J:$J,MOVIMIENTOS!$E:$E,$A48,MOVIMIENTOS!$B:$B,$B$3,MOVIMIENTOS!$C:$C,G$5,MOVIMIENTOS!$D:$D,"Ingreso") | H48: =SUMIFS(MOVIMIENTOS!$J:$J,MOVIMIENTOS!$E:$E,$A48,MOVIMIENTOS!$B:$B,$B$3,MOVIMIENTOS!$C:$C,H$5,MOVIMIENTOS!$D:$D,"Ingreso") | I48: =SUMIFS(MOVIMIENTOS!$J:$J,MOVIMIENTOS!$E:$E,$A48,MOVIMIENTOS!$B:$B,$B$3,MOVIMIENTOS!$C:$C,I$5,MOVIMIENTOS!$D:$D,"Ingreso") | ... M48: =SUMIFS(MOVIMIENTOS!$J:$J,MOVIMIENTOS!$E:$E,$A48,MOVIMIENTOS!$B:$B,$B$3,MOVIMIENTOS!$C:$C,M$5,MOVIMIENTOS!$D:$D,"Ingreso") | N48: =SUM($B48:$M48)
A49: TOTAL INGRESOS | B49: =SUM(B40:B48) | C49: =SUM(C40:C48) | D49: =SUM(D40:D48) | E49: =SUM(E40:E48) | F49: =SUM(F40:F48) | G49: =SUM(G40:G48) | H49: =SUM(H40:H48) | I49: =SUM(I40:I48) | ... N49: =SUM(N40:N48)
A51: RESULTADO (Ingresos - Gastos) | B51: =B49-B36 | C51: =C49-C36 | D51: =D49-D36 | E51: =E49-E36 | F51: =F49-F36 | G51: =G49-G36 | H51: =H49-H36 | I51: =I49-I36 | ... N51: =N49-N36
A53: Todos los importes estan expresados en U$D (columna Importe U$D de MOVIMIENTOS).
A54: Si preferis verlo en pesos, multiplica por la cotizacion del mes de la solapa CONFIG.

Sheet PRESUPUESTO
A1: PRESUPUESTO VS REAL
A2: Poné cuanto pensas gastar por mes en cada categoria. La planilla compara contra lo que gastaste de verdad.
A3: AÑO: | B3: =+'RESUMEN MENSUAL'!$B$3 | C3: (toma el año del RESUMEN MENSUAL)
A5: CATEGORIA | B5: Presupuesto Mensual | C5: Presupuesto Año | D5: Gasto Real Año | E5: Desvio | F5: % Usado | G5: Semaforo
A6: Vivienda | B6: 0 | C6: =$B6*12 | D6: =IFERROR(VLOOKUP($A6,'RESUMEN MENSUAL'!$A$7:$N$35,14,FALSE),0) | E6: =$C6-$D6 | F6: =IF($C6=0,"",$D6/$C6) | G6: =IF($C6=0,"sin presupuesto",IF($D6>$C6,"EXCEDIDO",IF($D6>$C6*0.9,"al limite","ok")))
A7: Servicios | B7: 0 | C7: =$B7*12 | D7: =IFERROR(VLOOKUP($A7,'RESUMEN MENSUAL'!$A$7:$N$35,14,FALSE),0) | E7: =$C7-$D7 | F7: =IF($C7=0,"",$D7/$C7) | G7: =IF($C7=0,"sin presupuesto",IF($D7>$C7,"EXCEDIDO",IF($D7>$C7*0.9,"al limite","ok")))
A8: Impuestos y Tasas | B8: 0 | C8: =$B8*12 | D8: =IFERROR(VLOOKUP($A8,'RESUMEN MENSUAL'!$A$7:$N$35,14,FALSE),0) | E8: =$C8-$D8 | F8: =IF($C8=0,"",$D8/$C8) | G8: =IF($C8=0,"sin presupuesto",IF($D8>$C8,"EXCEDIDO",IF($D8>$C8*0.9,"al limite","ok")))
A9: Supermercado | B9: 0 | C9: =$B9*12 | D9: =IFERROR(VLOOKUP($A9,'RESUMEN MENSUAL'!$A$7:$N$35,14,FALSE),0) | E9: =$C9-$D9 | F9: =IF($C9=0,"",$D9/$C9) | G9: =IF($C9=0,"sin presupuesto",IF($D9>$C9,"EXCEDIDO",IF($D9>$C9*0.9,"al limite","ok")))
A10: Comida y Salidas | B10: 0 | C10: =$B10*12 | D10: =IFERROR(VLOOKUP($A10,'RESUMEN MENSUAL'!$A$7:$N$35,14,FALSE),0) | E10: =$C10-$D10 | F10: =IF($C10=0,"",$D10/$C10) | G10: =IF($C10=0,"sin presupuesto",IF($D10>$C10,"EXCEDIDO",IF($D10>$C10*0.9,"al limite","ok")))
A11: Transporte | B11: 0 | C11: =$B11*12 | D11: =IFERROR(VLOOKUP($A11,'RESUMEN MENSUAL'!$A$7:$N$35,14,FALSE),0) | E11: =$C11-$D11 | F11: =IF($C11=0,"",$D11/$C11) | G11: =IF($C11=0,"sin presupuesto",IF($D11>$C11,"EXCEDIDO",IF($D11>$C11*0.9,"al limite","ok")))
A12: Combustible | B12: 0 | C12: =$B12*12 | D12: =IFERROR(VLOOKUP($A12,'RESUMEN MENSUAL'!$A$7:$N$35,14,FALSE),0) | E12: =$C12-$D12 | F12: =IF($C12=0,"",$D12/$C12) | G12: =IF($C12=0,"sin presupuesto",IF($D12>$C12,"EXCEDIDO",IF($D12>$C12*0.9,"al limite","ok")))
A13: Vehiculos - Mantenimiento | B13: 0 | C13: =$B13*12 | D13: =IFERROR(VLOOKUP($A13,'RESUMEN MENSUAL'!$A$7:$N$35,14,FALSE),0) | E13: =$C13-$D13 | F13: =IF($C13=0,"",$D13/$C13) | G13: =IF($C13=0,"sin presupuesto",IF($D13>$C13,"EXCEDIDO",IF($D13>$C13*0.9,"al limite","ok")))
A14: Seguros | B14: 0 | C14: =$B14*12 | D14: =IFERROR(VLOOKUP($A14,'RESUMEN MENSUAL'!$A$7:$N$35,14,FALSE),0) | E14: =$C14-$D14 | F14: =IF($C14=0,"",$D14/$C14) | G14: =IF($C14=0,"sin presupuesto",IF($D14>$C14,"EXCEDIDO",IF($D14>$C14*0.9,"al limite","ok")))
A15: Salud | B15: 0 | C15: =$B15*12 | D15: =IFERROR(VLOOKUP($A15,'RESUMEN MENSUAL'!$A$7:$N$35,14,FALSE),0) | E15: =$C15-$D15 | F15: =IF($C15=0,"",$D15/$C15) | G15: =IF($C15=0,"sin presupuesto",IF($D15>$C15,"EXCEDIDO",IF($D15>$C15*0.9,"al limite","ok")))
A16: Educacion | B16: 0 | C16: =$B16*12 | D16: =IFERROR(VLOOKUP($A16,'RESUMEN MENSUAL'!$A$7:$N$35,14,FALSE),0) | E16: =$C16-$D16 | F16: =IF($C16=0,"",$D16/$C16) | G16: =IF($C16=0,"sin presupuesto",IF($D16>$C16,"EXCEDIDO",IF($D16>$C16*0.9,"al limite","ok")))
A17: Indumentaria | B17: 0 | C17: =$B17*12 | D17: =IFERROR(VLOOKUP($A17,'RESUMEN MENSUAL'!$A$7:$N$35,14,FALSE),0) | E17: =$C17-$D17 | F17: =IF($C17=0,"",$D17/$C17) | G17: =IF($C17=0,"sin presupuesto",IF($D17>$C17,"EXCEDIDO",IF($D17>$C17*0.9,"al limite","ok")))
... A34: Gastos Varios | B34: 0 | C34: =$B34*12 | D34: =IFERROR(VLOOKUP($A34,'RESUMEN MENSUAL'!$A$7:$N$35,14,FALSE),0) | E34: =$C34-$D34 | F34: =IF($C34=0,"",$D34/$C34) | G34: =IF($C34=0,"sin presupuesto",IF($D34>$C34,"EXCEDIDO",IF($D34>$C34*0.9,"al limite","ok")))
A35: TOTAL | B35: =SUM(B6:B34) | C35: =SUM(C6:C34) | D35: =SUM(D6:D34) | E35: =SUM(E6:E34)

Sheet TABLERO
A1: TABLERO DEL AÑO
A2: Los numeros grandes. Todo se calcula solo.
A3: AÑO: | B3: =+'RESUMEN MENSUAL'!$B$3
A5: Total Ingresos del año (U$D) | B5: =+'RESUMEN MENSUAL'!$N$49 | D5: TOP CATEGORIAS DE GASTO DEL AÑO
A6: Total Gastos del año (U$D) | B6: =+'RESUMEN MENSUAL'!$N$36 | D6: Categoria | E6: Gasto U$D
A7: Resultado del año (U$D) | B7: =+'RESUMEN MENSUAL'!$N$51 | D7: =IFERROR(IF(LARGE('RESUMEN MENSUAL'!$N$7:$N$35,1)=0,"",INDEX('RESUMEN MENSUAL'!$A$7:$A$35,MATCH(LARGE('RESUMEN MENSUAL'!$N$7:$N$35,1),'RESUMEN MENSUAL'!$N$7:$N$35,0))),"") | E7: =IFERROR(IF(LARGE('RESUMEN MENSUAL'!$N$7:$N$35,1)=0,"",LARGE('RESUMEN MENSUAL'!$N$7:$N$35,1)),"")
A8: Gasto promedio por mes (U$D) | B8: =IFERROR(AVERAGE('RESUMEN MENSUAL'!$B$36:$M$36),0) | D8: =IFERROR(IF(LARGE('RESUMEN MENSUAL'!$N$7:$N$35,2)=0,"",INDEX('RESUMEN MENSUAL'!$A$7:$A$35,MATCH(LARGE('RESUMEN MENSUAL'!$N$7:$N$35,2),'RESUMEN MENSUAL'!$N$7:$N$35,0))),"") | E8: =IFERROR(IF(LARGE('RESUMEN MENSUAL'!$N$7:$N$35,2)=0,"",LARGE('RESUMEN MENSUAL'!$N$7:$N$35,2)),"")
A9: Mes de mayor gasto | B9: =IFERROR(INDEX('RESUMEN MENSUAL'!$B$6:$M$6,MATCH(MAX('RESUMEN MENSUAL'!$B$36:$M$36),'RESUMEN MENSUAL'!$B$36:$M$36,0)),"-") | D9: =IFERROR(IF(LARGE('RESUMEN MENSUAL'!$N$7:$N$35,3)=0,"",INDEX('RESUMEN MENSUAL'!$A$7:$A$35,MATCH(LARGE('RESUMEN MENSUAL'!$N$7:$N$35,3),'RESUMEN MENSUAL'!$N$7:$N$35,0))),"") | E9: =IFERROR(IF(LARGE('RESUMEN MENSUAL'!$N$7:$N$35,3)=0,"",LARGE('RESUMEN MENSUAL'!$N$7:$N$35,3)),"")
A10: Mayor gasto de un mes (U$D) | B10: =MAX('RESUMEN MENSUAL'!$B$36:$M$36) | D10: =IFERROR(IF(LARGE('RESUMEN MENSUAL'!$N$7:$N$35,4)=0,"",INDEX('RESUMEN MENSUAL'!$A$7:$A$35,MATCH(LARGE('RESUMEN MENSUAL'!$N$7:$N$35,4),'RESUMEN MENSUAL'!$N$7:$N$35,0))),"") | E10: =IFERROR(IF(LARGE('RESUMEN MENSUAL'!$N$7:$N$35,4)=0,"",LARGE('RESUMEN MENSUAL'!$N$7:$N$35,4)),"")
A11: Movimientos cargados | B11: =COUNTA(MOVIMIENTOS!$A$5:$A$804) | D11: =IFERROR(IF(LARGE('RESUMEN MENSUAL'!$N$7:$N$35,5)=0,"",INDEX('RESUMEN MENSUAL'!$A$7:$A$35,MATCH(LARGE('RESUMEN MENSUAL'!$N$7:$N$35,5),'RESUMEN MENSUAL'!$N$7:$N$35,0))),"") | E11: =IFERROR(IF(LARGE('RESUMEN MENSUAL'!$N$7:$N$35,5)=0,"",LARGE('RESUMEN MENSUAL'!$N$7:$N$35,5)),"")
A12: Gastos pendientes de pago (U$D) | B12: =SUMIFS(MOVIMIENTOS!$J:$J,MOVIMIENTOS!$L:$L,"Pendiente",MOVIMIENTOS!$D:$D,"Gasto") | D12: =IFERROR(IF(LARGE('RESUMEN MENSUAL'!$N$7:$N$35,6)=0,"",INDEX('RESUMEN MENSUAL'!$A$7:$A$35,MATCH(LARGE('RESUMEN MENSUAL'!$N$7:$N$35,6),'RESUMEN MENSUAL'!$N$7:$N$35,0))),"") | E12: =IFERROR(IF(LARGE('RESUMEN MENSUAL'!$N$7:$N$35,6)=0,"",LARGE('RESUMEN MENSUAL'!$N$7:$N$35,6)),"")
A13: Saldo en cuotas por pagar ($) | B13: =+'TARJETAS Y CUOTAS'!$J$87 | D13: =IFERROR(IF(LARGE('RESUMEN MENSUAL'!$N$7:$N$35,7)=0,"",INDEX('RESUMEN MENSUAL'!$A$7:$A$35,MATCH(LARGE('RESUMEN MENSUAL'!$N$7:$N$35,7),'RESUMEN MENSUAL'!$N$7:$N$35,0))),"") | E13: =IFERROR(IF(LARGE('RESUMEN MENSUAL'!$N$7:$N$35,7)=0,"",LARGE('RESUMEN MENSUAL'!$N$7:$N$35,7)),"")
A14: Total gastos fijos activos ($) | B14: =+'GASTOS FIJOS'!$C$66 | D14: =IFERROR(IF(LARGE('RESUMEN MENSUAL'!$N$7:$N$35,8)=0,"",INDEX('RESUMEN MENSUAL'!$A$7:$A$35,MATCH(LARGE('RESUMEN MENSUAL'!$N$7:$N$35,8),'RESUMEN MENSUAL'!$N$7:$N$35,0))),"") | E14: =IFERROR(IF(LARGE('RESUMEN MENSUAL'!$N$7:$N$35,8)=0,"",LARGE('RESUMEN MENSUAL'!$N$7:$N$35,8)),"")
D15: =IFERROR(IF(LARGE('RESUMEN MENSUAL'!$N$7:$N$35,9)=0,"",INDEX('RESUMEN MENSUAL'!$A$7:$A$35,MATCH(LARGE('RESUMEN MENSUAL'!$N$7:$N$35,9),'RESUMEN MENSUAL'!$N$7:$N$35,0))),"") | E15: =IFERROR(IF(LARGE('RESUMEN MENSUAL'!$N$7:$N$35,9)=0,"",LARGE('RESUMEN MENSUAL'!$N$7:$N$35,9)),"")
A16: Los importes en U$D salen de la columna Importe U$D de MOVIMIENTOS. | D16: =IFERROR(IF(LARGE('RESUMEN MENSUAL'!$N$7:$N$35,10)=0,"",INDEX('RESUMEN MENSUAL'!$A$7:$A$35,MATCH(LARGE('RESUMEN MENSUAL'!$N$7:$N$35,10),'RESUMEN MENSUAL'!$N$7:$N$35,0))),"") | E16: =IFERROR(IF(LARGE('RESUMEN MENSUAL'!$N$7:$N$35,10)=0,"",LARGE('RESUMEN MENSUAL'!$N$7:$N$35,10)),"")
A17: Los que dicen ($) estan en pesos porque vienen de las solapas de fijos y cuotas.
D18: Si dos categorias empatan puede repetirse el nombre; es normal.
